Workbook
Name Width: #REF!

Sheet NEW SHOES
A1: REVISION DATE: | E1: FALL 2026 PROGRAM NEW SHOES | X1: RWSS | AJ1: F26_RWSS_L1 | AK1: H - 90 FFT
A2: 121125 | AH2: Order Grand Total | AJ2: F26_RWSS_L2 | AK2: L - 2% FFT
A3: PROGRAM A | P3: DOMESTIC-A | Y3: Select Dropdown | AA3: GRAND TOTAL FOOTWEAR | AG3: =AG5+EXISTING!AF6+'EUROPEAN SHOES'!AC5 -> 95 | AH3: =AG4+'CARE PRODUCTS & MISC'!Q3 -> 17421 | AJ3: F26 RWSS NO TERMS | AK3: M - 180 FFT
A4: NEW AND SEASONAL | E4: DATE: | M4: ACCOUNT # | W4: NO | AA4: GRAND TOTAL FOOTWEAR $ | AG4: =AG6+EXISTING!AF7+'EUROPEAN SHOES'!AC6 -> 14250 | AH4: DEALERSHIP TERMS OPTIONS | AK4: N - 4% FFT | AR4: RWBR | AS4: M
B5: Please enter last name only -------> | E5: SALES REP: | L5: STORE NAME: | W5: change to YES for address change | AA5: NEW SHOES TOTAL | AG5: =A14+A23+A27+A35+A47+A65+A69+A73+A77+A85+A89+A97 -> 95 | AH5: NEW SHOES L1 | AI5: OPTED OUT OF RECOMMENDATION (terms H or L) | AK5: O - 180 4% | AR5: WORX | AS5: W
E6: P.O. #: | F6: =IF(F7="",F8,F7) -> F26 A | M6: ADDRESS: | AA6: NEW SHOES TOTAL $ | AG6: =A15+A24+A28+A36+A48+A66+A74+A78+A86+A90+A98+A70 -> 14250 | AH6: NEW SHOES L2 | AI6: RECOMMENDATION SELECTED (terms M, N, O, or P) | AK6: P - 8% | AL6: A | AM6: NO | AR6: Irish Setter
E7: PO ENTRY: | N7: CITY: | AA7: TERMS: | AK7: F - NO TERMS | AL7: B | AM7: YES | AR7: Rubber
E8: Default PO | F8: F26 A | N8: STATE: | S8: ZIP CODE: | AH8: Footwear Tabs: New Shoes Colored Tab: Only New Accessories Available | AL8: C
A9: ALL HIGHLIGHTED FIELDS ARE REQUIRED FIELDS | AA9: OUR REFERENCE: | AL9: D
AJ10: Customer Order Number (Internal use only)
B11: Package | C11: CO TYPE | D11: Ship Date | E11: Style | F11: Width | G11: 1 | H11: 2 | I11: 3 | J11: 4 | K11: 4.5 | L11: 5 | M11: 5.5 | N11: 6 | O11: 6.5 | P11: 7 | Q11: 7.5 | R11: 8 | S11: 8.5 | T11: 9 | U11: 9.5 | V11: 10 | W11: 10.5 | X11: 11 | Y11: 11.5 | Z11: 12 | AA11: 13 | AB11: 14 | AC11: 15 | AD11: 16 | AE11: 17 | AF11: 18 | AG11: Total Pair | AH11: Price/Pr | AI11: Total Price /PR | AT11: Package (hide) | AU11: Brand | AV11: Gender
A12: RED WING | C12: UNF | D12: 101526 | E12: 2543 | F12: D | L12: =IF(IF($AT12<>"",VLOOKUP(CONCATENATE($AT12,$AU12,$AV12,$F12),'SKU Dist'!$E$2:$X$200,'SKU Dist'!F$1,FALSE),"")=0,"",IF($AT12<>"",VLOOKUP(CONCATENATE($AT12,$AU12,$AV12,$F12),'SKU Dist'!$E$2:$X$200,'SKU Dist'!F$1,FALSE),"")) | M12: =IF(IF($AT12<>"",VLOOKUP(CONCATENATE($AT12,$AU12,$AV12,$F12),'SKU Dist'!$E$2:$X$200,'SKU Dist'!G$1,FALSE),"")=0,"",IF($AT12<>"",VLOOKUP(CONCATENATE($AT12,$AU12,$AV12,$F12),'SKU Dist'!$E$2:$X$200,'SKU Dist'!G$1,FALSE),"")) | N12: =IF(IF($AT12<>"",VLOOKUP(CONCATENATE($AT12,$AU12,$AV12,$F12),'SKU Dist'!$E$2:$X$200,'SKU Dist'!H$1,FALSE),"")=0,"",IF($AT12<>"",VLOOKUP(CONCATENATE($AT12,$AU12,$AV12,$F12),'SKU Dist'!$E$2:$X$200,'SKU Dist'!H$1,FALSE),"")) | O12: =IF(IF($AT12<>"",VLOOKUP(CONCATENATE($AT12,$AU12,$AV12,$F12),'SKU Dist'!$E$2:$X$200,'SKU Dist'!I$1,FALSE),"")=0,"",IF($AT12<>"",VLOOKUP(CONCATENATE($AT12,$AU12,$AV12,$F12),'SKU Dist'!$E$2:$X$200,'SKU Dist'!I$1,FALSE),"")) | P12: =IF(IF($AT12<>"",VLOOKUP(CONCATENATE($AT12,$AU12,$AV12,$F12),'SKU Dist'!$E$2:$X$200,'SKU Dist'!J$1,FALSE),"")=0,"",IF($AT12<>"",VLOOKUP(CONCATENATE($AT12,$AU12,$AV12,$F12),'SKU Dist'!$E$2:$X$200,'SKU Dist'!J$1,FALSE),"")) | Q12: =IF(IF($AT12<>"",VLOOKUP(CONCATENATE($AT12,$AU12,$AV12,$F12),'SKU Dist'!$E$2:$X$200,'SKU Dist'!K$1,FALSE),"")=0,"",IF($AT12<>"",VLOOKUP(CONCATENATE($AT12,$AU12,$AV12,$F12),'SKU Dist'!$E$2:$X$200,'SKU Dist'!K$1,FALSE),"")) | R12: =IF(IF($AT12<>"",VLOOKUP(CONCATENATE($AT12,$AU12,$AV12,$F12),'SKU Dist'!$E$2:$X$200,'SKU Dist'!L$1,FALSE),"")=0,"",IF($AT12<>"",VLOOKUP(CONCATENATE($AT12,$AU12,$AV12,$F12),'SKU Dist'!$E$2:$X$200,'SKU Dist'!L$1,FALSE),"")) | S12: 1 | T12: 1 | U12: 2 | V12: 2 | W12: 2 | X12: 2 | Y12: 1 | Z12: 2 | AA12: =IF(IF($AT12<>"",VLOOKUP(CONCATENATE($AT12,$AU12,$AV12,$F12),'SKU Dist'!$E$2:$X$200,'SKU Dist'!U$1,FALSE),"")=0,"",IF($AT12<>"",VLOOKUP(CONCATENATE($AT12,$AU12,$AV12,$F12),'SKU Dist'!$E$2:$X$200,'SKU Dist'!U$1,FALSE),"")) | AB12: =IF(IF($AT12<>"",VLOOKUP(CONCATENATE($AT12,$AU12,$AV12,$F12),'SKU Dist'!$E$2:$X$200,'SKU Dist'!V$1,FALSE),"")=0,"",IF($AT12<>"",VLOOKUP(CONCATENATE($AT12,$AU12,$AV12,$F12),'SKU Dist'!$E$2:$X$200,'SKU Dist'!V$1,FALSE),"")) | AC12: =IF(IF($AT12<>"",VLOOKUP(CONCATENATE($AT12,$AU12,$AV12,$F12),'SKU Dist'!$E$2:$X$200,'SKU Dist'!W$1,FALSE),"")=0,"",IF($AT12<>"",VLOOKUP(CONCATENATE($AT12,$AU12,$AV12,$F12),'SKU Dist'!$E$2:$X$200,'SKU Dist'!W$1,FALSE),"")) | AG12: =SUM(G12:AF12) -> 13 | AH12: 180 | AI12: =AG12*AH12 -> 2340 | AT12: =IF(E12=E11,AT11,IF(B12="","",B12)) | AU12: RWBR | AV12: M
A13: SuperSole X | C13: UNF | D13: 101526 | E13: 2543 | F13: E2 | L13: =IF(IF($AT13<>"",VLOOKUP(CONCATENATE($AT13,$AU13,$AV13,$F13),'SKU Dist'!$E$2:$X$200,'SKU Dist'!F$1,FALSE),"")=0,"",IF($AT13<>"",VLOOKUP(CONCATENATE($AT13,$AU13,$AV13,$F13),'SKU Dist'!$E$2:$X$200,'SKU Dist'!F$1,FALSE),"")) | M13: =IF(IF($AT13<>"",VLOOKUP(CONCATENATE($AT13,$AU13,$AV13,$F13),'SKU Dist'!$E$2:$X$200,'SKU Dist'!G$1,FALSE),"")=0,"",IF($AT13<>"",VLOOKUP(CONCATENATE($AT13,$AU13,$AV13,$F13),'SKU Dist'!$E$2:$X$200,'SKU Dist'!G$1,FALSE),"")) | N13: =IF(IF($AT13<>"",VLOOKUP(CONCATENATE($AT13,$AU13,$AV13,$F13),'SKU Dist'!$E$2:$X$200,'SKU Dist'!H$1,FALSE),"")=0,"",IF($AT13<>"",VLOOKUP(CONCATENATE($AT13,$AU13,$AV13,$F13),'SKU Dist'!$E$2:$X$200,'SKU Dist'!H$1,FALSE),"")) | O13: =IF(IF($AT13<>"",VLOOKUP(CONCATENATE($AT13,$AU13,$AV13,$F13),'SKU Dist'!$E$2:$X$200,'SKU Dist'!I$1,FALSE),"")=0,"",IF($AT13<>"",VLOOKUP(CONCATENATE($AT13,$AU13,$AV13,$F13),'SKU Dist'!$E$2:$X$200,'SKU Dist'!I$1,FALSE),"")) | P13: =IF(IF($AT13<>"",VLOOKUP(CONCATENATE($AT13,$AU13,$AV13,$F13),'SKU Dist'!$E$2:$X$200,'SKU Dist'!J$1,FALSE),"")=0,"",IF($AT13<>"",VLOOKUP(CONCATENATE($AT13,$AU13,$AV13,$F13),'SKU Dist'!$E$2:$X$200,'SKU Dist'!J$1,FALSE),"")) | Q13: =IF(IF($AT13<>"",VLOOKUP(CONCATENATE($AT13,$AU13,$AV13,$F13),'SKU Dist'!$E$2:$X$200,'SKU Dist'!K$1,FALSE),"")=0,"",IF($AT13<>"",VLOOKUP(CONCATENATE($AT13,$AU13,$AV13,$F13),'SKU Dist'!$E$2:$X$200,'SKU Dist'!K$1,FALSE),"")) | R13: =IF(IF($AT13<>"",VLOOKUP(CONCATENATE($AT13,$AU13,$AV13,$F13),'SKU Dist'!$E$2:$X$200,'SKU Dist'!L$1,FALSE),"")=0,"",IF($AT13<>"",VLOOKUP(CONCATENATE($AT13,$AU13,$AV13,$F13),'SKU Dist'!$E$2:$X$200,'SKU Dist'!L$1,FALSE),"")) | T13: 1 | U13: 1 | V13: 1 | W13: 1 | X13: 1 | Z13: 1 | AA13: =IF(IF($AT13<>"",VLOOKUP(CONCATENATE($AT13,$AU13,$AV13,$F13),'SKU Dist'!$E$2:$X$200,'SKU Dist'!U$1,FALSE),"")=0,"",IF($AT13<>"",VLOOKUP(CONCATENATE($AT13,$AU13,$AV13,$F13),'SKU Dist'!$E$2:$X$200,'SKU Dist'!U$1,FALSE),"")) | AB13: =IF(IF($AT13<>"",VLOOKUP(CONCATENATE($AT13,$AU13,$AV13,$F13),'SKU Dist'!$E$2:$X$200,'SKU Dist'!V$1,FALSE),"")=0,"",IF($AT13<>"",VLOOKUP(CONCATENATE($AT13,$AU13,$AV13,$F13),'SKU Dist'!$E$2:$X$200,'SKU Dist'!V$1,FALSE),"")) | AG13: =SUM(G13:AF13) -> 6 | AH13: 180 | AI13: =AG13*AH13 -> 1080 | AT13: =IF(E13=E12,AT12,IF(B13="","",B13)) | AU13: RWBR | AV13: M
A14: =SUM(AG12:AG20) -> 19 | C14: UNF | D14: 101526 | E14: 2543 | F14: E3 | L14: =IF(IF($AT14<>"",VLOOKUP(CONCATENATE($AT14,$AU14,$AV14,$F14),'SKU Dist'!$E$2:$X$200,'SKU Dist'!F$1,FALSE),"")=0,"",IF($AT14<>"",VLOOKUP(CONCATENATE($AT14,$AU14,$AV14,$F14),'SKU Dist'!$E$2:$X$200,'SKU Dist'!F$1,FALSE),"")) | M14: =IF(IF($AT14<>"",VLOOKUP(CONCATENATE($AT14,$AU14,$AV14,$F14),'SKU Dist'!$E$2:$X$200,'SKU Dist'!G$1,FALSE),"")=0,"",IF($AT14<>"",VLOOKUP(CONCATENATE($AT14,$AU14,$AV14,$F14),'SKU Dist'!$E$2:$X$200,'SKU Dist'!G$1,FALSE),"")) | N14: =IF(IF($AT14<>"",VLOOKUP(CONCATENATE($AT14,$AU14,$AV14,$F14),'SKU Dist'!$E$2:$X$200,'SKU Dist'!H$1,FALSE),"")=0,"",IF($AT14<>"",VLOOKUP(CONCATENATE($AT14,$AU14,$AV14,$F14),'SKU Dist'!$E$2:$X$200,'SKU Dist'!H$1,FALSE),"")) | O14: =IF(IF($AT14<>"",VLOOKUP(CONCATENATE($AT14,$AU14,$AV14,$F14),'SKU Dist'!$E$2:$X$200,'SKU Dist'!I$1,FALSE),"")=0,"",IF($AT14<>"",VLOOKUP(CONCATENATE($AT14,$AU14,$AV14,$F14),'SKU Dist'!$E$2:$X$200,'SKU Dist'!I$1,FALSE),"")) | P14: =IF(IF($AT14<>"",VLOOKUP(CONCATENATE($AT14,$AU14,$AV14,$F14),'SKU Dist'!$E$2:$X$200,'SKU Dist'!J$1,FALSE),"")=0,"",IF($AT14<>"",VLOOKUP(CONCATENATE($AT14,$AU14,$AV14,$F14),'SKU Dist'!$E$2:$X$200,'SKU Dist'!J$1,FALSE),"")) | Q14: =IF(IF($AT14<>"",VLOOKUP(CONCATENATE($AT14,$AU14,$AV14,$F14),'SKU Dist'!$E$2:$X$200,'SKU Dist'!K$1,FALSE),"")=0,"",IF($AT14<>"",VLOOKUP(CONCATENATE($AT14,$AU14,$AV14,$F14),'SKU Dist'!$E$2:$X$200,'SKU Dist'!K$1,FALSE),"")) | R14: =IF(IF($AT14<>"",VLOOKUP(CONCATENATE($AT14,$AU14,$AV14,$F14),'SKU Dist'!$E$2:$X$200,'SKU Dist'!L$1,FALSE),"")=0,"",IF($AT14<>"",VLOOKUP(CONCATENATE($AT14,$AU14,$AV14,$F14),'SKU Dist'!$E$2:$X$200,'SKU Dist'!L$1,FALSE),"")) | S14: =IF(IF($AT14<>"",VLOOKUP(CONCATENATE($AT14,$AU14,$AV14,$F14),'SKU Dist'!$E$2:$X$200,'SKU Dist'!M$1,FALSE),"")=0,"",IF($AT14<>"",VLOOKUP(CONCATENATE($AT14,$AU14,$AV14,$F14),'SKU Dist'!$E$2:$X$200,'SKU Dist'!M$1,FALSE),"")) | ... AB14: =IF(IF($AT14<>"",VLOOKUP(CONCATENATE($AT14,$AU14,$AV14,$F14),'SKU Dist'!$E$2:$X$200,'SKU Dist'!V$1,FALSE),"")=0,"",IF($AT14<>"",VLOOKUP(CONCATENATE($AT14,$AU14,$AV14,$F14),'SKU Dist'!$E$2:$X$200,'SKU Dist'!V$1,FALSE),"")) | AG14: =SUM(G14:AF14) -> 0 | AH14: 180 | AI14: =AG14*AH14 -> 0 | AT14: =IF(E14=E13,AT13,IF(B14="","",B14)) | AU14: RWBR | AV14: M
A15: =SUM(AI12:AI20) -> 3420 | C15: UNF | D15: 101526 | E15: 3577 | F15: D | L15: =IF(IF($AT15<>"",VLOOKUP(CONCATENATE($AT15,$AU15,$AV15,$F15),'SKU Dist'!$E$2:$X$200,'SKU Dist'!F$1,FALSE),"")=0,"",IF($AT15<>"",VLOOKUP(CONCATENATE($AT15,$AU15,$AV15,$F15),'SKU Dist'!$E$2:$X$200,'SKU Dist'!F$1,FALSE),"")) | M15: =IF(IF($AT15<>"",VLOOKUP(CONCATENATE($AT15,$AU15,$AV15,$F15),'SKU Dist'!$E$2:$X$200,'SKU Dist'!G$1,FALSE),"")=0,"",IF($AT15<>"",VLOOKUP(CONCATENATE($AT15,$AU15,$AV15,$F15),'SKU Dist'!$E$2:$X$200,'SKU Dist'!G$1,FALSE),"")) | N15: =IF(IF($AT15<>"",VLOOKUP(CONCATENATE($AT15,$AU15,$AV15,$F15),'SKU Dist'!$E$2:$X$200,'SKU Dist'!H$1,FALSE),"")=0,"",IF($AT15<>"",VLOOKUP(CONCATENATE($AT15,$AU15,$AV15,$F15),'SKU Dist'!$E$2:$X$200,'SKU Dist'!H$1,FALSE),"")) | O15: =IF(IF($AT15<>"",VLOOKUP(CONCATENATE($AT15,$AU15,$AV15,$F15),'SKU Dist'!$E$2:$X$200,'SKU Dist'!I$1,FALSE),"")=0,"",IF($AT15<>"",VLOOKUP(CONCATENATE($AT15,$AU15,$AV15,$F15),'SKU Dist'!$E$2:$X$200,'SKU Dist'!I$1,FALSE),"")) | P15: =IF(IF($AT15<>"",VLOOKUP(CONCATENATE($AT15,$AU15,$AV15,$F15),'SKU Dist'!$E$2:$X$200,'SKU Dist'!J$1,FALSE),"")=0,"",IF($AT15<>"",VLOOKUP(CONCATENATE($AT15,$AU15,$AV15,$F15),'SKU Dist'!$E$2:$X$200,'SKU Dist'!J$1,FALSE),"")) | Q15: =IF(IF($AT15<>"",VLOOKUP(CONCATENATE($AT15,$AU15,$AV15,$F15),'SKU Dist'!$E$2:$X$200,'SKU Dist'!K$1,FALSE),"")=0,"",IF($AT15<>"",VLOOKUP(CONCATENATE($AT15,$AU15,$AV15,$F15),'SKU Dist'!$E$2:$X$200,'SKU Dist'!K$1,FALSE),"")) | R15: =IF(IF($AT15<>"",VLOOKUP(CONCATENATE($AT15,$AU15,$AV15,$F15),'SKU Dist'!$E$2:$X$200,'SKU Dist'!L$1,FALSE),"")=0,"",IF($AT15<>"",VLOOKUP(CONCATENATE($AT15,$AU15,$AV15,$F15),'SKU Dist'!$E$2:$X$200,'SKU Dist'!L$1,FALSE),"")) | S15: =IF(IF($AT15<>"",VLOOKUP(CONCATENATE($AT15,$AU15,$AV15,$F15),'SKU Dist'!$E$2:$X$200,'SKU Dist'!M$1,FALSE),"")=0,"",IF($AT15<>"",VLOOKUP(CONCATENATE($AT15,$AU15,$AV15,$F15),'SKU Dist'!$E$2:$X$200,'SKU Dist'!M$1,FALSE),"")) | ... AC15: =IF(IF($AT15<>"",VLOOKUP(CONCATENATE($AT15,$AU15,$AV15,$F15),'SKU Dist'!$E$2:$X$200,'SKU Dist'!W$1,FALSE),"")=0,"",IF($AT15<>"",VLOOKUP(CONCATENATE($AT15,$AU15,$AV15,$F15),'SKU Dist'!$E$2:$X$200,'SKU Dist'!W$1,FALSE),"")) | AG15: =SUM(G15:AF15) -> 0 | AH15: 190 | AI15: =AG15*AH15 -> 0 | AT15: =IF(E15=E14,AT14,IF(B15="","",B15)) | AU15: RWBR | AV15: M
C16: UNF | D16: 101526 | E16: 3577 | F16: E2 | L16: =IF(IF($AT16<>"",VLOOKUP(CONCATENATE($AT16,$AU16,$AV16,$F16),'SKU Dist'!$E$2:$X$200,'SKU Dist'!F$1,FALSE),"")=0,"",IF($AT16<>"",VLOOKUP(CONCATENATE($AT16,$AU16,$AV16,$F16),'SKU Dist'!$E$2:$X$200,'SKU Dist'!F$1,FALSE),"")) | M16: =IF(IF($AT16<>"",VLOOKUP(CONCATENATE($AT16,$AU16,$AV16,$F16),'SKU Dist'!$E$2:$X$200,'SKU Dist'!G$1,FALSE),"")=0,"",IF($AT16<>"",VLOOKUP(CONCATENATE($AT16,$AU16,$AV16,$F16),'SKU Dist'!$E$2:$X$200,'SKU Dist'!G$1,FALSE),"")) | N16: =IF(IF($AT16<>"",VLOOKUP(CONCATENATE($AT16,$AU16,$AV16,$F16),'SKU Dist'!$E$2:$X$200,'SKU Dist'!H$1,FALSE),"")=0,"",IF($AT16<>"",VLOOKUP(CONCATENATE($AT16,$AU16,$AV16,$F16),'SKU Dist'!$E$2:$X$200,'SKU Dist'!H$1,FALSE),"")) | O16: =IF(IF($AT16<>"",VLOOKUP(CONCATENATE($AT16,$AU16,$AV16,$F16),'SKU Dist'!$E$2:$X$200,'SKU Dist'!I$1,FALSE),"")=0,"",IF($AT16<>"",VLOOKUP(CONCATENATE($AT16,$AU16,$AV16,$F16),'SKU Dist'!$E$2:$X$200,'SKU Dist'!I$1,FALSE),"")) | P16: =IF(IF($AT16<>"",VLOOKUP(CONCATENATE($AT16,$AU16,$AV16,$F16),'SKU Dist'!$E$2:$X$200,'SKU Dist'!J$1,FALSE),"")=0,"",IF($AT16<>"",VLOOKUP(CONCATENATE($AT16,$AU16,$AV16,$F16),'SKU Dist'!$E$2:$X$200,'SKU Dist'!J$1,FALSE),"")) | Q16: =IF(IF($AT16<>"",VLOOKUP(CONCATENATE($AT16,$AU16,$AV16,$F16),'SKU Dist'!$E$2:$X$200,'SKU Dist'!K$1,FALSE),"")=0,"",IF($AT16<>"",VLOOKUP(CONCATENATE($AT16,$AU16,$AV16,$F16),'SKU Dist'!$E$2:$X$200,'SKU Dist'!K$1,FALSE),"")) | R16: =IF(IF($AT16<>"",VLOOKUP(CONCATENATE($AT16,$AU16,$AV16,$F16),'SKU Dist'!$E$2:$X$200,'SKU Dist'!L$1,FALSE),"")=0,"",IF($AT16<>"",VLOOKUP(CONCATENATE($AT16,$AU16,$AV16,$F16),'SKU Dist'!$E$2:$X$200,'SKU Dist'!L$1,FALSE),"")) | S16: =IF(IF($AT16<>"",VLOOKUP(CONCATENATE($AT16,$AU16,$AV16,$F16),'SKU Dist'!$E$2:$X$200,'SKU Dist'!M$1,FALSE),"")=0,"",IF($AT16<>"",VLOOKUP(CONCATENATE($AT16,$AU16,$AV16,$F16),'SKU Dist'!$E$2:$X$200,'SKU Dist'!M$1,FALSE),"")) | ... AB16: =IF(IF($AT16<>"",VLOOKUP(CONCATENATE($AT16,$AU16,$AV16,$F16),'SKU Dist'!$E$2:$X$200,'SKU Dist'!V$1,FALSE),"")=0,"",IF($AT16<>"",VLOOKUP(CONCATENATE($AT16,$AU16,$AV16,$F16),'SKU Dist'!$E$2:$X$200,'SKU Dist'!V$1,FALSE),"")) | AG16: =SUM(G16:AF16) -> 0 | AH16: 190 | AI16: =AG16*AH16 -> 0 | AT16: =IF(E16=E15,AT15,IF(B16="","",B16)) | AU16: RWBR | AV16: M
C17: UNF | D17: 101526 | E17: 3577 | F17: E3 | L17: =IF(IF($AT17<>"",VLOOKUP(CONCATENATE($AT17,$AU17,$AV17,$F17),'SKU Dist'!$E$2:$X$200,'SKU Dist'!F$1,FALSE),"")=0,"",IF($AT17<>"",VLOOKUP(CONCATENATE($AT17,$AU17,$AV17,$F17),'SKU Dist'!$E$2:$X$200,'SKU Dist'!F$1,FALSE),"")) | M17: =IF(IF($AT17<>"",VLOOKUP(CONCATENATE($AT17,$AU17,$AV17,$F17),'SKU Dist'!$E$2:$X$200,'SKU Dist'!G$1,FALSE),"")=0,"",IF($AT17<>"",VLOOKUP(CONCATENATE($AT17,$AU17,$AV17,$F17),'SKU Dist'!$E$2:$X$200,'SKU Dist'!G$1,FALSE),"")) | N17: =IF(IF($AT17<>"",VLOOKUP(CONCATENATE($AT17,$AU17,$AV17,$F17),'SKU Dist'!$E$2:$X$200,'SKU Dist'!H$1,FALSE),"")=0,"",IF($AT17<>"",VLOOKUP(CONCATENATE($AT17,$AU17,$AV17,$F17),'SKU Dist'!$E$2:$X$200,'SKU Dist'!H$1,FALSE),"")) | O17: =IF(IF($AT17<>"",VLOOKUP(CONCATENATE($AT17,$AU17,$AV17,$F17),'SKU Dist'!$E$2:$X$200,'SKU Dist'!I$1,FALSE),"")=0,"",IF($AT17<>"",VLOOKUP(CONCATENATE($AT17,$AU17,$AV17,$F17),'SKU Dist'!$E$2:$X$200,'SKU Dist'!I$1,FALSE),"")) | P17: =IF(IF($AT17<>"",VLOOKUP(CONCATENATE($AT17,$AU17,$AV17,$F17),'SKU Dist'!$E$2:$X$200,'SKU Dist'!J$1,FALSE),"")=0,"",IF($AT17<>"",VLOOKUP(CONCATENATE($AT17,$AU17,$AV17,$F17),'SKU Dist'!$E$2:$X$200,'SKU Dist'!J$1,FALSE),"")) | Q17: =IF(IF($AT17<>"",VLOOKUP(CONCATENATE($AT17,$AU17,$AV17,$F17),'SKU Dist'!$E$2:$X$200,'SKU Dist'!K$1,FALSE),"")=0,"",IF($AT17<>"",VLOOKUP(CONCATENATE($AT17,$AU17,$AV17,$F17),'SKU Dist'!$E$2:$X$200,'SKU Dist'!K$1,FALSE),"")) | R17: =IF(IF($AT17<>"",VLOOKUP(CONCATENATE($AT17,$AU17,$AV17,$F17),'SKU Dist'!$E$2:$X$200,'SKU Dist'!L$1,FALSE),"")=0,"",IF($AT17<>"",VLOOKUP(CONCATENATE($AT17,$AU17,$AV17,$F17),'SKU Dist'!$E$2:$X$200,'SKU Dist'!L$1,FALSE),"")) | S17: =IF(IF($AT17<>"",VLOOKUP(CONCATENATE($AT17,$AU17,$AV17,$F17),'SKU Dist'!$E$2:$X$200,'SKU Dist'!M$1,FALSE),"")=0,"",IF($AT17<>"",VLOOKUP(CONCATENATE($AT17,$AU17,$AV17,$F17),'SKU Dist'!$E$2:$X$200,'SKU Dist'!M$1,FALSE),"")) | ... AB17: =IF(IF($AT17<>"",VLOOKUP(CONCATENATE($AT17,$AU17,$AV17,$F17),'SKU Dist'!$E$2:$X$200,'SKU Dist'!V$1,FALSE),"")=0,"",IF($AT17<>"",VLOOKUP(CONCATENATE($AT17,$AU17,$AV17,$F17),'SKU Dist'!$E$2:$X$200,'SKU Dist'!V$1,FALSE),"")) | AG17: =SUM(G17:AF17) -> 0 | AH17: 190 | AI17: =AG17*AH17 -> 0 | AT17: =IF(E17=E16,AT16,IF(B17="","",B17)) | AU17: RWBR | AV17: M
C18: UNF | D18: 101526 | E18: 3580 | F18: D | L18: =IF(IF($AT18<>"",VLOOKUP(CONCATENATE($AT18,$AU18,$AV18,$F18),'SKU Dist'!$E$2:$X$200,'SKU Dist'!F$1,FALSE),"")=0,"",IF($AT18<>"",VLOOKUP(CONCATENATE($AT18,$AU18,$AV18,$F18),'SKU Dist'!$E$2:$X$200,'SKU Dist'!F$1,FALSE),"")) | M18: =IF(IF($AT18<>"",VLOOKUP(CONCATENATE($AT18,$AU18,$AV18,$F18),'SKU Dist'!$E$2:$X$200,'SKU Dist'!G$1,FALSE),"")=0,"",IF($AT18<>"",VLOOKUP(CONCATENATE($AT18,$AU18,$AV18,$F18),'SKU Dist'!$E$2:$X$200,'SKU Dist'!G$1,FALSE),"")) | N18: =IF(IF($AT18<>"",VLOOKUP(CONCATENATE($AT18,$AU18,$AV18,$F18),'SKU Dist'!$E$2:$X$200,'SKU Dist'!H$1,FALSE),"")=0,"",IF($AT18<>"",VLOOKUP(CONCATENATE($AT18,$AU18,$AV18,$F18),'SKU Dist'!$E$2:$X$200,'SKU Dist'!H$1,FALSE),"")) | O18: =IF(IF($AT18<>"",VLOOKUP(CONCATENATE($AT18,$AU18,$AV18,$F18),'SKU Dist'!$E$2:$X$200,'SKU Dist'!I$1,FALSE),"")=0,"",IF($AT18<>"",VLOOKUP(CONCATENATE($AT18,$AU18,$AV18,$F18),'SKU Dist'!$E$2:$X$200,'SKU Dist'!I$1,FALSE),"")) | P18: =IF(IF($AT18<>"",VLOOKUP(CONCATENATE($AT18,$AU18,$AV18,$F18),'SKU Dist'!$E$2:$X$200,'SKU Dist'!J$1,FALSE),"")=0,"",IF($AT18<>"",VLOOKUP(CONCATENATE($AT18,$AU18,$AV18,$F18),'SKU Dist'!$E$2:$X$200,'SKU Dist'!J$1,FALSE),"")) | Q18: =IF(IF($AT18<>"",VLOOKUP(CONCATENATE($AT18,$AU18,$AV18,$F18),'SKU Dist'!$E$2:$X$200,'SKU Dist'!K$1,FALSE),"")=0,"",IF($AT18<>"",VLOOKUP(CONCATENATE($AT18,$AU18,$AV18,$F18),'SKU Dist'!$E$2:$X$200,'SKU Dist'!K$1,FALSE),"")) | R18: =IF(IF($AT18<>"",VLOOKUP(CONCATENATE($AT18,$AU18,$AV18,$F18),'SKU Dist'!$E$2:$X$200,'SKU Dist'!L$1,FALSE),"")=0,"",IF($AT18<>"",VLOOKUP(CONCATENATE($AT18,$AU18,$AV18,$F18),'SKU Dist'!$E$2:$X$200,'SKU Dist'!L$1,FALSE),"")) | S18: =IF(IF($AT18<>"",VLOOKUP(CONCATENATE($AT18,$AU18,$AV18,$F18),'SKU Dist'!$E$2:$X$200,'SKU Dist'!M$1,FALSE),"")=0,"",IF($AT18<>"",VLOOKUP(CONCATENATE($AT18,$AU18,$AV18,$F18),'SKU Dist'!$E$2:$X$200,'SKU Dist'!M$1,FALSE),"")) | ... AC18: =IF(IF($AT18<>"",VLOOKUP(CONCATENATE($AT18,$AU18,$AV18,$F18),'SKU Dist'!$E$2:$X$200,'SKU Dist'!W$1,FALSE),"")=0,"",IF($AT18<>"",VLOOKUP(CONCATENATE($AT18,$AU18,$AV18,$F18),'SKU Dist'!$E$2:$X$200,'SKU Dist'!W$1,FALSE),"")) | AG18: =SUM(G18:AF18) -> 0 | AH18: 190 | AI18: =AG18*AH18 -> 0 | AT18: =IF(E18=E17,AT17,IF(B18="","",B18)) | AU18: RWBR | AV18: M
C19: UNF | D19: 101526 | E19: 3580 | F19: E2 | L19: =IF(IF($AT19<>"",VLOOKUP(CONCATENATE($AT19,$AU19,$AV19,$F19),'SKU Dist'!$E$2:$X$200,'SKU Dist'!F$1,FALSE),"")=0,"",IF($AT19<>"",VLOOKUP(CONCATENATE($AT19,$AU19,$AV19,$F19),'SKU Dist'!$E$2:$X$200,'SKU Dist'!F$1,FALSE),"")) | M19: =IF(IF($AT19<>"",VLOOKUP(CONCATENATE($AT19,$AU19,$AV19,$F19),'SKU Dist'!$E$2:$X$200,'SKU Dist'!G$1,FALSE),"")=0,"",IF($AT19<>"",VLOOKUP(CONCATENATE($AT19,$AU19,$AV19,$F19),'SKU Dist'!$E$2:$X$200,'SKU Dist'!G$1,FALSE),"")) | N19: =IF(IF($AT19<>"",VLOOKUP(CONCATENATE($AT19,$AU19,$AV19,$F19),'SKU Dist'!$E$2:$X$200,'SKU Dist'!H$1,FALSE),"")=0,"",IF($AT19<>"",VLOOKUP(CONCATENATE($AT19,$AU19,$AV19,$F19),'SKU Dist'!$E$2:$X$200,'SKU Dist'!H$1,FALSE),"")) | O19: =IF(IF($AT19<>"",VLOOKUP(CONCATENATE($AT19,$AU19,$AV19,$F19),'SKU Dist'!$E$2:$X$200,'SKU Dist'!I$1,FALSE),"")=0,"",IF($AT19<>"",VLOOKUP(CONCATENATE($AT19,$AU19,$AV19,$F19),'SKU Dist'!$E$2:$X$200,'SKU Dist'!I$1,FALSE),"")) | P19: =IF(IF($AT19<>"",VLOOKUP(CONCATENATE($AT19,$AU19,$AV19,$F19),'SKU Dist'!$E$2:$X$200,'SKU Dist'!J$1,FALSE),"")=0,"",IF($AT19<>"",VLOOKUP(CONCATENATE($AT19,$AU19,$AV19,$F19),'SKU Dist'!$E$2:$X$200,'SKU Dist'!J$1,FALSE),"")) | Q19: =IF(IF($AT19<>"",VLOOKUP(CONCATENATE($AT19,$AU19,$AV19,$F19),'SKU Dist'!$E$2:$X$200,'SKU Dist'!K$1,FALSE),"")=0,"",IF($AT19<>"",VLOOKUP(CONCATENATE($AT19,$AU19,$AV19,$F19),'SKU Dist'!$E$2:$X$200,'SKU Dist'!K$1,FALSE),"")) | R19: =IF(IF($AT19<>"",VLOOKUP(CONCATENATE($AT19,$AU19,$AV19,$F19),'SKU Dist'!$E$2:$X$200,'SKU Dist'!L$1,FALSE),"")=0,"",IF($AT19<>"",VLOOKUP(CONCATENATE($AT19,$AU19,$AV19,$F19),'SKU Dist'!$E$2:$X$200,'SKU Dist'!L$1,FALSE),"")) | S19: =IF(IF($AT19<>"",VLOOKUP(CONCATENATE($AT19,$AU19,$AV19,$F19),'SKU Dist'!$E$2:$X$200,'SKU Dist'!M$1,FALSE),"")=0,"",IF($AT19<>"",VLOOKUP(CONCATENATE($AT19,$AU19,$AV19,$F19),'SKU Dist'!$E$2:$X$200,'SKU Dist'!M$1,FALSE),"")) | ... AB19: =IF(IF($AT19<>"",VLOOKUP(CONCATENATE($AT19,$AU19,$AV19,$F19),'SKU Dist'!$E$2:$X$200,'SKU Dist'!V$1,FALSE),"")=0,"",IF($AT19<>"",VLOOKUP(CONCATENATE($AT19,$AU19,$AV19,$F19),'SKU Dist'!$E$2:$X$200,'SKU Dist'!V$1,FALSE),"")) | AG19: =SUM(G19:AF19) -> 0 | AH19: 190 | AI19: =AG19*AH19 -> 0 | AT19: =IF(E19=E18,AT18,IF(B19="","",B19)) | AU19: RWBR | AV19: M
C20: UNF | D20: 101526 | E20: 3580 | F20: E3 | L20: =IF(IF($AT20<>"",VLOOKUP(CONCATENATE($AT20,$AU20,$AV20,$F20),'SKU Dist'!$E$2:$X$200,'SKU Dist'!F$1,FALSE),"")=0,"",IF($AT20<>"",VLOOKUP(CONCATENATE($AT20,$AU20,$AV20,$F20),'SKU Dist'!$E$2:$X$200,'SKU Dist'!F$1,FALSE),"")) | M20: =IF(IF($AT20<>"",VLOOKUP(CONCATENATE($AT20,$AU20,$AV20,$F20),'SKU Dist'!$E$2:$X$200,'SKU Dist'!G$1,FALSE),"")=0,"",IF($AT20<>"",VLOOKUP(CONCATENATE($AT20,$AU20,$AV20,$F20),'SKU Dist'!$E$2:$X$200,'SKU Dist'!G$1,FALSE),"")) | N20: =IF(IF($AT20<>"",VLOOKUP(CONCATENATE($AT20,$AU20,$AV20,$F20),'SKU Dist'!$E$2:$X$200,'SKU Dist'!H$1,FALSE),"")=0,"",IF($AT20<>"",VLOOKUP(CONCATENATE($AT20,$AU20,$AV20,$F20),'SKU Dist'!$E$2:$X$200,'SKU Dist'!H$1,FALSE),"")) | O20: =IF(IF($AT20<>"",VLOOKUP(CONCATENATE($AT20,$AU20,$AV20,$F20),'SKU Dist'!$E$2:$X$200,'SKU Dist'!I$1,FALSE),"")=0,"",IF($AT20<>"",VLOOKUP(CONCATENATE($AT20,$AU20,$AV20,$F20),'SKU Dist'!$E$2:$X$200,'SKU Dist'!I$1,FALSE),"")) | P20: =IF(IF($AT20<>"",VLOOKUP(CONCATENATE($AT20,$AU20,$AV20,$F20),'SKU Dist'!$E$2:$X$200,'SKU Dist'!J$1,FALSE),"")=0,"",IF($AT20<>"",VLOOKUP(CONCATENATE($AT20,$AU20,$AV20,$F20),'SKU Dist'!$E$2:$X$200,'SKU Dist'!J$1,FALSE),"")) | Q20: =IF(IF($AT20<>"",VLOOKUP(CONCATENATE($AT20,$AU20,$AV20,$F20),'SKU Dist'!$E$2:$X$200,'SKU Dist'!K$1,FALSE),"")=0,"",IF($AT20<>"",VLOOKUP(CONCATENATE($AT20,$AU20,$AV20,$F20),'SKU Dist'!$E$2:$X$200,'SKU Dist'!K$1,FALSE),"")) | R20: =IF(IF($AT20<>"",VLOOKUP(CONCATENATE($AT20,$AU20,$AV20,$F20),'SKU Dist'!$E$2:$X$200,'SKU Dist'!L$1,FALSE),"")=0,"",IF($AT20<>"",VLOOKUP(CONCATENATE($AT20,$AU20,$AV20,$F20),'SKU Dist'!$E$2:$X$200,'SKU Dist'!L$1,FALSE),"")) | S20: =IF(IF($AT20<>"",VLOOKUP(CONCATENATE($AT20,$AU20,$AV20,$F20),'SKU Dist'!$E$2:$X$200,'SKU Dist'!M$1,FALSE),"")=0,"",IF($AT20<>"",VLOOKUP(CONCATENATE($AT20,$AU20,$AV20,$F20),'SKU Dist'!$E$2:$X$200,'SKU Dist'!M$1,FALSE),"")) | ... AB20: =IF(IF($AT20<>"",VLOOKUP(CONCATENATE($AT20,$AU20,$AV20,$F20),'SKU Dist'!$E$2:$X$200,'SKU Dist'!V$1,FALSE),"")=0,"",IF($AT20<>"",VLOOKUP(CONCATENATE($AT20,$AU20,$AV20,$F20),'SKU Dist'!$E$2:$X$200,'SKU Dist'!V$1,FALSE),"")) | AG20: =SUM(G20:AF20) -> 0 | AH20: 190 | AI20: =AG20*AH20 -> 0 | AT20: =IF(E20=E19,AT19,IF(B20="","",B20)) | AU20: RWBR | AV20: M
A21: RED WING | C21: KHR | D21: 081526 | E21: 3593 | F21: D | N21: =IF(IF($AT21<>"",VLOOKUP(CONCATENATE($AT21,$AU21,$AV21,$F21),'SKU Dist'!$E$2:$X$200,'SKU Dist'!H$1,FALSE),"")=0,"",IF($AT21<>"",VLOOKUP(CONCATENATE($AT21,$AU21,$AV21,$F21),'SKU Dist'!$E$2:$X$200,'SKU Dist'!H$1,FALSE),"")) | O21: =IF(IF($AT21<>"",VLOOKUP(CONCATENATE($AT21,$AU21,$AV21,$F21),'SKU Dist'!$E$2:$X$200,'SKU Dist'!I$1,FALSE),"")=0,"",IF($AT21<>"",VLOOKUP(CONCATENATE($AT21,$AU21,$AV21,$F21),'SKU Dist'!$E$2:$X$200,'SKU Dist'!I$1,FALSE),"")) | P21: =IF(IF($AT21<>"",VLOOKUP(CONCATENATE($AT21,$AU21,$AV21,$F21),'SKU Dist'!$E$2:$X$200,'SKU Dist'!J$1,FALSE),"")=0,"",IF($AT21<>"",VLOOKUP(CONCATENATE($AT21,$AU21,$AV21,$F21),'SKU Dist'!$E$2:$X$200,'SKU Dist'!J$1,FALSE),"")) | Q21: =IF(IF($AT21<>"",VLOOKUP(CONCATENATE($AT21,$AU21,$AV21,$F21),'SKU Dist'!$E$2:$X$200,'SKU Dist'!K$1,FALSE),"")=0,"",IF($AT21<>"",VLOOKUP(CONCATENATE($AT21,$AU21,$AV21,$F21),'SKU Dist'!$E$2:$X$200,'SKU Dist'!K$1,FALSE),"")) | R21: =IF(IF($AT21<>"",VLOOKUP(CONCATENATE($AT21,$AU21,$AV21,$F21),'SKU Dist'!$E$2:$X$200,'SKU Dist'!L$1,FALSE),"")=0,"",IF($AT21<>"",VLOOKUP(CONCATENATE($AT21,$AU21,$AV21,$F21),'SKU Dist'!$E$2:$X$200,'SKU Dist'!L$1,FALSE),"")) | AA21: =IF(IF($AT21<>"",VLOOKUP(CONCATENATE($AT21,$AU21,$AV21,$F21),'SKU Dist'!$E$2:$X$200,'SKU Dist'!U$1,FALSE),"")=0,"",IF($AT21<>"",VLOOKUP(CONCATENATE($AT21,$AU21,$AV21,$F21),'SKU Dist'!$E$2:$X$200,'SKU Dist'!U$1,FALSE),"")) | AB21: =IF(IF($AT21<>"",VLOOKUP(CONCATENATE($AT21,$AU21,$AV21,$F21),'SKU Dist'!$E$2:$X$200,'SKU Dist'!V$1,FALSE),"")=0,"",IF($AT21<>"",VLOOKUP(CONCATENATE($AT21,$AU21,$AV21,$F21),'SKU Dist'!$E$2:$X$200,'SKU Dist'!V$1,FALSE),"")) | AG21: =SUM(G21:AF21) -> 0 | AH21: 157.5 | AI21: =AG21*AH21 -> 0 | AT21: =IF(E21=E15,AT15,IF(B21="","",B21)) | AU21: RWBR | AV21: M
A22: ExosLite | C22: KHR | D22: 081526 | E22: 3593 | F22: E2 | N22: =IF(IF($AT22<>"",VLOOKUP(CONCATENATE($AT22,$AU22,$AV22,$F22),'SKU Dist'!$E$2:$X$200,'SKU Dist'!H$1,FALSE),"")=0,"",IF($AT22<>"",VLOOKUP(CONCATENATE($AT22,$AU22,$AV22,$F22),'SKU Dist'!$E$2:$X$200,'SKU Dist'!H$1,FALSE),"")) | O22: =IF(IF($AT22<>"",VLOOKUP(CONCATENATE($AT22,$AU22,$AV22,$F22),'SKU Dist'!$E$2:$X$200,'SKU Dist'!I$1,FALSE),"")=0,"",IF($AT22<>"",VLOOKUP(CONCATENATE($AT22,$AU22,$AV22,$F22),'SKU Dist'!$E$2:$X$200,'SKU Dist'!I$1,FALSE),"")) | P22: =IF(IF($AT22<>"",VLOOKUP(CONCATENATE($AT22,$AU22,$AV22,$F22),'SKU Dist'!$E$2:$X$200,'SKU Dist'!J$1,FALSE),"")=0,"",IF($AT22<>"",VLOOKUP(CONCATENATE($AT22,$AU22,$AV22,$F22),'SKU Dist'!$E$2:$X$200,'SKU Dist'!J$1,FALSE),"")) | Q22: =IF(IF($AT22<>"",VLOOKUP(CONCATENATE($AT22,$AU22,$AV22,$F22),'SKU Dist'!$E$2:$X$200,'SKU Dist'!K$1,FALSE),"")=0,"",IF($AT22<>"",VLOOKUP(CONCATENATE($AT22,$AU22,$AV22,$F22),'SKU Dist'!$E$2:$X$200,'SKU Dist'!K$1,FALSE),"")) | R22: =IF(IF($AT22<>"",VLOOKUP(CONCATENATE($AT22,$AU22,$AV22,$F22),'SKU Dist'!$E$2:$X$200,'SKU Dist'!L$1,FALSE),"")=0,"",IF($AT22<>"",VLOOKUP(CONCATENATE($AT22,$AU22,$AV22,$F22),'SKU Dist'!$E$2:$X$200,'SKU Dist'!L$1,FALSE),"")) | AA22: =IF(IF($AT22<>"",VLOOKUP(CONCATENATE($AT22,$AU22,$AV22,$F22),'SKU Dist'!$E$2:$X$200,'SKU Dist'!U$1,FALSE),"")=0,"",IF($AT22<>"",VLOOKUP(CONCATENATE($AT22,$AU22,$AV22,$F22),'SKU Dist'!$E$2:$X$200,'SKU Dist'!U$1,FALSE),"")) | AB22: =IF(IF($AT22<>"",VLOOKUP(CONCATENATE($AT22,$AU22,$AV22,$F22),'SKU Dist'!$E$2:$X$200,'SKU Dist'!V$1,FALSE),"")=0,"",IF($AT22<>"",VLOOKUP(CONCATENATE($AT22,$AU22,$AV22,$F22),'SKU Dist'!$E$2:$X$200,'SKU Dist'!V$1,FALSE),"")) | AG22: =SUM(G22:AF22) -> 0 | AH22: 157.5 | AI22: =AG22*AH22 -> 0 | AT22: =IF(E22=E16,AT16,IF(B22="","",B22)) | AU22: RWBR | AV22: M
A23: =SUM(AG21:AG24) -> 0 | C23: KHR | D23: 081526 | E23: 3593 | F23: H | R23: =IF(IF($AT23<>"",VLOOKUP(CONCATENATE($AT23,$AU23,$AV23,$F23),'SKU Dist'!$E$2:$X$200,'SKU Dist'!L$1,FALSE),"")=0,"",IF($AT23<>"",VLOOKUP(CONCATENATE($AT23,$AU23,$AV23,$F23),'SKU Dist'!$E$2:$X$200,'SKU Dist'!L$1,FALSE),"")) | S23: =IF(IF($AT23<>"",VLOOKUP(CONCATENATE($AT23,$AU23,$AV23,$F23),'SKU Dist'!$E$2:$X$200,'SKU Dist'!M$1,FALSE),"")=0,"",IF($AT23<>"",VLOOKUP(CONCATENATE($AT23,$AU23,$AV23,$F23),'SKU Dist'!$E$2:$X$200,'SKU Dist'!M$1,FALSE),"")) | T23: =IF(IF($AT23<>"",VLOOKUP(CONCATENATE($AT23,$AU23,$AV23,$F23),'SKU Dist'!$E$2:$X$200,'SKU Dist'!N$1,FALSE),"")=0,"",IF($AT23<>"",VLOOKUP(CONCATENATE($AT23,$AU23,$AV23,$F23),'SKU Dist'!$E$2:$X$200,'SKU Dist'!N$1,FALSE),"")) | U23: =IF(IF($AT23<>"",VLOOKUP(CONCATENATE($AT23,$AU23,$AV23,$F23),'SKU Dist'!$E$2:$X$200,'SKU Dist'!O$1,FALSE),"")=0,"",IF($AT23<>"",VLOOKUP(CONCATENATE($AT23,$AU23,$AV23,$F23),'SKU Dist'!$E$2:$X$200,'SKU Dist'!O$1,FALSE),"")) | V23: =IF(IF($AT23<>"",VLOOKUP(CONCATENATE($AT23,$AU23,$AV23,$F23),'SKU Dist'!$E$2:$X$200,'SKU Dist'!P$1,FALSE),"")=0,"",IF($AT23<>"",VLOOKUP(CONCATENATE($AT23,$AU23,$AV23,$F23),'SKU Dist'!$E$2:$X$200,'SKU Dist'!P$1,FALSE),"")) | W23: =IF(IF($AT23<>"",VLOOKUP(CONCATENATE($AT23,$AU23,$AV23,$F23),'SKU Dist'!$E$2:$X$200,'SKU Dist'!Q$1,FALSE),"")=0,"",IF($AT23<>"",VLOOKUP(CONCATENATE($AT23,$AU23,$AV23,$F23),'SKU Dist'!$E$2:$X$200,'SKU Dist'!Q$1,FALSE),"")) | X23: =IF(IF($AT23<>"",VLOOKUP(CONCATENATE($AT23,$AU23,$AV23,$F23),'SKU Dist'!$E$2:$X$200,'SKU Dist'!R$1,FALSE),"")=0,"",IF($AT23<>"",VLOOKUP(CONCATENATE($AT23,$AU23,$AV23,$F23),'SKU Dist'!$E$2:$X$200,'SKU Dist'!R$1,FALSE),"")) | Y23: =IF(IF($AT23<>"",VLOOKUP(CONCATENATE($AT23,$AU23,$AV23,$F23),'SKU Dist'!$E$2:$X$200,'SKU Dist'!S$1,FALSE),"")=0,"",IF($AT23<>"",VLOOKUP(CONCATENATE($AT23,$AU23,$AV23,$F23),'SKU Dist'!$E$2:$X$200,'SKU Dist'!S$1,FALSE),"")) | ... AB23: =IF(IF($AT23<>"",VLOOKUP(CONCATENATE($AT23,$AU23,$AV23,$F23),'SKU Dist'!$E$2:$X$200,'SKU Dist'!V$1,FALSE),"")=0,"",IF($AT23<>"",VLOOKUP(CONCATENATE($AT23,$AU23,$AV23,$F23),'SKU Dist'!$E$2:$X$200,'SKU Dist'!V$1,FALSE),"")) | AG23: =SUM(G23:AF23) -> 0 | AH23: 157.5 | AI23: =AG23*AH23 -> 0 | AT23: =IF(E23=E17,AT17,IF(B23="","",B23)) | AU23: RWBR | AV23: M
A24: =SUM(AI21:AI23) -> 0 | AT24: =IF(E24=E21,AT21,IF(B24="","",B24)) | AU24: RWBR | AV24: M
A25: RED WING | C25: VNR | D25: 081526 | E25: 3740 | F25: D | N25: =IF(IF($AT25<>"",VLOOKUP(CONCATENATE($AT25,$AU25,$AV25,$F25),'SKU Dist'!$E$2:$X$200,'SKU Dist'!H$1,FALSE),"")=0,"",IF($AT25<>"",VLOOKUP(CONCATENATE($AT25,$AU25,$AV25,$F25),'SKU Dist'!$E$2:$X$200,'SKU Dist'!H$1,FALSE),"")) | O25: =IF(IF($AT25<>"",VLOOKUP(CONCATENATE($AT25,$AU25,$AV25,$F25),'SKU Dist'!$E$2:$X$200,'SKU Dist'!I$1,FALSE),"")=0,"",IF($AT25<>"",VLOOKUP(CONCATENATE($AT25,$AU25,$AV25,$F25),'SKU Dist'!$E$2:$X$200,'SKU Dist'!I$1,FALSE),"")) | P25: =IF(IF($AT25<>"",VLOOKUP(CONCATENATE($AT25,$AU25,$AV25,$F25),'SKU Dist'!$E$2:$X$200,'SKU Dist'!J$1,FALSE),"")=0,"",IF($AT25<>"",VLOOKUP(CONCATENATE($AT25,$AU25,$AV25,$F25),'SKU Dist'!$E$2:$X$200,'SKU Dist'!J$1,FALSE),"")) | Q25: =IF(IF($AT25<>"",VLOOKUP(CONCATENATE($AT25,$AU25,$AV25,$F25),'SKU Dist'!$E$2:$X$200,'SKU Dist'!K$1,FALSE),"")=0,"",IF($AT25<>"",VLOOKUP(CONCATENATE($AT25,$AU25,$AV25,$F25),'SKU Dist'!$E$2:$X$200,'SKU Dist'!K$1,FALSE),"")) | R25: =IF(IF($AT25<>"",VLOOKUP(CONCATENATE($AT25,$AU25,$AV25,$F25),'SKU Dist'!$E$2:$X$200,'SKU Dist'!L$1,FALSE),"")=0,"",IF($AT25<>"",VLOOKUP(CONCATENATE($AT25,$AU25,$AV25,$F25),'SKU Dist'!$E$2:$X$200,'SKU Dist'!L$1,FALSE),"")) | S25: 1 | T25: 1 | U25: 2 | V25: 2 | W25: 2 | X25: 2 | Y25: 1 | Z25: 2 | AA25: =IF(IF($AT25<>"",VLOOKUP(CONCATENATE($AT25,$AU25,$AV25,$F25),'SKU Dist'!$E$2:$X$200,'SKU Dist'!U$1,FALSE),"")=0,"",IF($AT25<>"",VLOOKUP(CONCATENATE($AT25,$AU25,$AV25,$F25),'SKU Dist'!$E$2:$X$200,'SKU Dist'!U$1,FALSE),"")) | AB25: =IF(IF($AT25<>"",VLOOKUP(CONCATENATE($AT25,$AU25,$AV25,$F25),'SKU Dist'!$E$2:$X$200,'SKU Dist'!V$1,FALSE),"")=0,"",IF($AT25<>"",VLOOKUP(CONCATENATE($AT25,$AU25,$AV25,$F25),'SKU Dist'!$E$2:$X$200,'SKU Dist'!V$1,FALSE),"")) | AC25: =IF(IF($AT25<>"",VLOOKUP(CONCATENATE($AT25,$AU25,$AV25,$F25),'SKU Dist'!$E$2:$X$200,'SKU Dist'!W$1,FALSE),"")=0,"",IF($AT25<>"",VLOOKUP(CONCATENATE($AT25,$AU25,$AV25,$F25),'SKU Dist'!$E$2:$X$200,'SKU Dist'!W$1,FALSE),"")) | AG25: =SUM(G25:AF25) -> 13 | AH25: 145 | AI25: =AG25*AH25 -> 1885 | AT25: =IF(E25=E22,AT22,IF(B25="","",B25)) | AU25: RWBR | AV25: M
A26: IronFlex | C26: VNR | D26: 081526 | E26: 3740 | F26: E2 | N26: =IF(IF($AT26<>"",VLOOKUP(CONCATENATE($AT26,$AU26,$AV26,$F26),'SKU Dist'!$E$2:$X$200,'SKU Dist'!H$1,FALSE),"")=0,"",IF($AT26<>"",VLOOKUP(CONCATENATE($AT26,$AU26,$AV26,$F26),'SKU Dist'!$E$2:$X$200,'SKU Dist'!H$1,FALSE),"")) | O26: =IF(IF($AT26<>"",VLOOKUP(CONCATENATE($AT26,$AU26,$AV26,$F26),'SKU Dist'!$E$2:$X$200,'SKU Dist'!I$1,FALSE),"")=0,"",IF($AT26<>"",VLOOKUP(CONCATENATE($AT26,$AU26,$AV26,$F26),'SKU Dist'!$E$2:$X$200,'SKU Dist'!I$1,FALSE),"")) | P26: =IF(IF($AT26<>"",VLOOKUP(CONCATENATE($AT26,$AU26,$AV26,$F26),'SKU Dist'!$E$2:$X$200,'SKU Dist'!J$1,FALSE),"")=0,"",IF($AT26<>"",VLOOKUP(CONCATENATE($AT26,$AU26,$AV26,$F26),'SKU Dist'!$E$2:$X$200,'SKU Dist'!J$1,FALSE),"")) | Q26: =IF(IF($AT26<>"",VLOOKUP(CONCATENATE($AT26,$AU26,$AV26,$F26),'SKU Dist'!$E$2:$X$200,'SKU Dist'!K$1,FALSE),"")=0,"",IF($AT26<>"",VLOOKUP(CONCATENATE($AT26,$AU26,$AV26,$F26),'SKU Dist'!$E$2:$X$200,'SKU Dist'!K$1,FALSE),"")) | R26: =IF(IF($AT26<>"",VLOOKUP(CONCATENATE($AT26,$AU26,$AV26,$F26),'SKU Dist'!$E$2:$X$200,'SKU Dist'!L$1,FALSE),"")=0,"",IF($AT26<>"",VLOOKUP(CONCATENATE($AT26,$AU26,$AV26,$F26),'SKU Dist'!$E$2:$X$200,'SKU Dist'!L$1,FALSE),"")) | T26: 1 | U26: 1 | V26: 1 | W26: 1 | X26: 1 | Z26: 1 | AA26: =IF(IF($AT26<>"",VLOOKUP(CONCATENATE($AT26,$AU26,$AV26,$F26),'SKU Dist'!$E$2:$X$200,'SKU Dist'!U$1,FALSE),"")=0,"",IF($AT26<>"",VLOOKUP(CONCATENATE($AT26,$AU26,$AV26,$F26),'SKU Dist'!$E$2:$X$200,'SKU Dist'!U$1,FALSE),"")) | AB26: =IF(IF($AT26<>"",VLOOKUP(CONCATENATE($AT26,$AU26,$AV26,$F26),'SKU Dist'!$E$2:$X$200,'SKU Dist'!V$1,FALSE),"")=0,"",IF($AT26<>"",VLOOKUP(CONCATENATE($AT26,$AU26,$AV26,$F26),'SKU Dist'!$E$2:$X$200,'SKU Dist'!V$1,FALSE),"")) | AC26: =IF(IF($AT26<>"",VLOOKUP(CONCATENATE($AT26,$AU26,$AV26,$F26),'SKU Dist'!$E$2:$X$200,'SKU Dist'!W$1,FALSE),"")=0,"",IF($AT26<>"",VLOOKUP(CONCATENATE($AT26,$AU26,$AV26,$F26),'SKU Dist'!$E$2:$X$200,'SKU Dist'!W$1,FALSE),"")) | AG26: =SUM(G26:AF26) -> 6 | AH26: 145 | AI26: =AG26*AH26 -> 870 | AT26: =IF(E26=E23,AT23,IF(B26="","",B26)) | AU26: RWBR | AV26: M
A27: =SUM(AG25:AG30) -> 19 | C27: VNR | D27: 081526 | E27: 3740 | F27: H | R27: =IF(IF($AT27<>"",VLOOKUP(CONCATENATE($AT27,$AU27,$AV27,$F27),'SKU Dist'!$E$2:$X$200,'SKU Dist'!L$1,FALSE),"")=0,"",IF($AT27<>"",VLOOKUP(CONCATENATE($AT27,$AU27,$AV27,$F27),'SKU Dist'!$E$2:$X$200,'SKU Dist'!L$1,FALSE),"")) | S27: =IF(IF($AT27<>"",VLOOKUP(CONCATENATE($AT27,$AU27,$AV27,$F27),'SKU Dist'!$E$2:$X$200,'SKU Dist'!M$1,FALSE),"")=0,"",IF($AT27<>"",VLOOKUP(CONCATENATE($AT27,$AU27,$AV27,$F27),'SKU Dist'!$E$2:$X$200,'SKU Dist'!M$1,FALSE),"")) | T27: =IF(IF($AT27<>"",VLOOKUP(CONCATENATE($AT27,$AU27,$AV27,$F27),'SKU Dist'!$E$2:$X$200,'SKU Dist'!N$1,FALSE),"")=0,"",IF($AT27<>"",VLOOKUP(CONCATENATE($AT27,$AU27,$AV27,$F27),'SKU Dist'!$E$2:$X$200,'SKU Dist'!N$1,FALSE),"")) | U27: =IF(IF($AT27<>"",VLOOKUP(CONCATENATE($AT27,$AU27,$AV27,$F27),'SKU Dist'!$E$2:$X$200,'SKU Dist'!O$1,FALSE),"")=0,"",IF($AT27<>"",VLOOKUP(CONCATENATE($AT27,$AU27,$AV27,$F27),'SKU Dist'!$E$2:$X$200,'SKU Dist'!O$1,FALSE),"")) | V27: =IF(IF($AT27<>"",VLOOKUP(CONCATENATE($AT27,$AU27,$AV27,$F27),'SKU Dist'!$E$2:$X$200,'SKU Dist'!P$1,FALSE),"")=0,"",IF($AT27<>"",VLOOKUP(CONCATENATE($AT27,$AU27,$AV27,$F27),'SKU Dist'!$E$2:$X$200,'SKU Dist'!P$1,FALSE),"")) | W27: =IF(IF($AT27<>"",VLOOKUP(CONCATENATE($AT27,$AU27,$AV27,$F27),'SKU Dist'!$E$2:$X$200,'SKU Dist'!Q$1,FALSE),"")=0,"",IF($AT27<>"",VLOOKUP(CONCATENATE($AT27,$AU27,$AV27,$F27),'SKU Dist'!$E$2:$X$200,'SKU Dist'!Q$1,FALSE),"")) | X27: =IF(IF($AT27<>"",VLOOKUP(CONCATENATE($AT27,$AU27,$AV27,$F27),'SKU Dist'!$E$2:$X$200,'SKU Dist'!R$1,FALSE),"")=0,"",IF($AT27<>"",VLOOKUP(CONCATENATE($AT27,$AU27,$AV27,$F27),'SKU Dist'!$E$2:$X$200,'SKU Dist'!R$1,FALSE),"")) | Y27: =IF(IF($AT27<>"",VLOOKUP(CONCATENATE($AT27,$AU27,$AV27,$F27),'SKU Dist'!$E$2:$X$200,'SKU Dist'!S$1,FALSE),"")=0,"",IF($AT27<>"",VLOOKUP(CONCATENATE($AT27,$AU27,$AV27,$F27),'SKU Dist'!$E$2:$X$200,'SKU Dist'!S$1,FALSE),"")) | ... AB27: =IF(IF($AT27<>"",VLOOKUP(CONCATENATE($AT27,$AU27,$AV27,$F27),'SKU Dist'!$E$2:$X$200,'SKU Dist'!V$1,FALSE),"")=0,"",IF($AT27<>"",VLOOKUP(CONCATENATE($AT27,$AU27,$AV27,$F27),'SKU Dist'!$E$2:$X$200,'SKU Dist'!V$1,FALSE),"")) | AG27: =SUM(G27:AF27) -> 0 | AH27: 145 | AI27: =AG27*AH27 -> 0 | AT27: =IF(E27=E26,AT26,IF(B27="","",B27)) | AU27: RWBR | AV27: M
A28: =SUM(AI25:AI30) -> 2755 | C28: VNR | D28: 081526 | E28: 3741 | F28: D | N28: =IF(IF($AT28<>"",VLOOKUP(CONCATENATE($AT28,$AU28,$AV28,$F28),'SKU Dist'!$E$2:$X$200,'SKU Dist'!H$1,FALSE),"")=0,"",IF($AT28<>"",VLOOKUP(CONCATENATE($AT28,$AU28,$AV28,$F28),'SKU Dist'!$E$2:$X$200,'SKU Dist'!H$1,FALSE),"")) | O28: =IF(IF($AT28<>"",VLOOKUP(CONCATENATE($AT28,$AU28,$AV28,$F28),'SKU Dist'!$E$2:$X$200,'SKU Dist'!I$1,FALSE),"")=0,"",IF($AT28<>"",VLOOKUP(CONCATENATE($AT28,$AU28,$AV28,$F28),'SKU Dist'!$E$2:$X$200,'SKU Dist'!I$1,FALSE),"")) | P28: =IF(IF($AT28<>"",VLOOKUP(CONCATENATE($AT28,$AU28,$AV28,$F28),'SKU Dist'!$E$2:$X$200,'SKU Dist'!J$1,FALSE),"")=0,"",IF($AT28<>"",VLOOKUP(CONCATENATE($AT28,$AU28,$AV28,$F28),'SKU Dist'!$E$2:$X$200,'SKU Dist'!J$1,FALSE),"")) | Q28: =IF(IF($AT28<>"",VLOOKUP(CONCATENATE($AT28,$AU28,$AV28,$F28),'SKU Dist'!$E$2:$X$200,'SKU Dist'!K$1,FALSE),"")=0,"",IF($AT28<>"",VLOOKUP(CONCATENATE($AT28,$AU28,$AV28,$F28),'SKU Dist'!$E$2:$X$200,'SKU Dist'!K$1,FALSE),"")) | R28: =IF(IF($AT28<>"",VLOOKUP(CONCATENATE($AT28,$AU28,$AV28,$F28),'SKU Dist'!$E$2:$X$200,'SKU Dist'!L$1,FALSE),"")=0,"",IF($AT28<>"",VLOOKUP(CONCATENATE($AT28,$AU28,$AV28,$F28),'SKU Dist'!$E$2:$X$200,'SKU Dist'!L$1,FALSE),"")) | S28: =IF(IF($AT28<>"",VLOOKUP(CONCATENATE($AT28,$AU28,$AV28,$F28),'SKU Dist'!$E$2:$X$200,'SKU Dist'!M$1,FALSE),"")=0,"",IF($AT28<>"",VLOOKUP(CONCATENATE($AT28,$AU28,$AV28,$F28),'SKU Dist'!$E$2:$X$200,'SKU Dist'!M$1,FALSE),"")) | T28: =IF(IF($AT28<>"",VLOOKUP(CONCATENATE($AT28,$AU28,$AV28,$F28),'SKU Dist'!$E$2:$X$200,'SKU Dist'!N$1,FALSE),"")=0,"",IF($AT28<>"",VLOOKUP(CONCATENATE($AT28,$AU28,$AV28,$F28),'SKU Dist'!$E$2:$X$200,'SKU Dist'!N$1,FALSE),"")) | U28: =IF(IF($AT28<>"",VLOOKUP(CONCATENATE($AT28,$AU28,$AV28,$F28),'SKU Dist'!$E$2:$X$200,'SKU Dist'!O$1,FALSE),"")=0,"",IF($AT28<>"",VLOOKUP(CONCATENATE($AT28,$AU28,$AV28,$F28),'SKU Dist'!$E$2:$X$200,'SKU Dist'!O$1,FALSE),"")) | ... AC28: =IF(IF($AT28<>"",VLOOKUP(CONCATENATE($AT28,$AU28,$AV28,$F28),'SKU Dist'!$E$2:$X$200,'SKU Dist'!W$1,FALSE),"")=0,"",IF($AT28<>"",VLOOKUP(CONCATENATE($AT28,$AU28,$AV28,$F28),'SKU Dist'!$E$2:$X$200,'SKU Dist'!W$1,FALSE),"")) | AG28: =SUM(G28:AF28) -> 0 | AH28: 130 | AI28: =AG28*AH28 -> 0 | AT28: =IF(E28=E27,AT27,IF(B28="","",B28)) | AU28: RWBR | AV28: M
C29: VNR | D29: 081526 | E29: 3741 | F29: E2 | N29: =IF(IF($AT29<>"",VLOOKUP(CONCATENATE($AT29,$AU29,$AV29,$F29),'SKU Dist'!$E$2:$X$200,'SKU Dist'!H$1,FALSE),"")=0,"",IF($AT29<>"",VLOOKUP(CONCATENATE($AT29,$AU29,$AV29,$F29),'SKU Dist'!$E$2:$X$200,'SKU Dist'!H$1,FALSE),"")) | O29: =IF(IF($AT29<>"",VLOOKUP(CONCATENATE($AT29,$AU29,$AV29,$F29),'SKU Dist'!$E$2:$X$200,'SKU Dist'!I$1,FALSE),"")=0,"",IF($AT29<>"",VLOOKUP(CONCATENATE($AT29,$AU29,$AV29,$F29),'SKU Dist'!$E$2:$X$200,'SKU Dist'!I$1,FALSE),"")) | P29: =IF(IF($AT29<>"",VLOOKUP(CONCATENATE($AT29,$AU29,$AV29,$F29),'SKU Dist'!$E$2:$X$200,'SKU Dist'!J$1,FALSE),"")=0,"",IF($AT29<>"",VLOOKUP(CONCATENATE($AT29,$AU29,$AV29,$F29),'SKU Dist'!$E$2:$X$200,'SKU Dist'!J$1,FALSE),"")) | Q29: =IF(IF($AT29<>"",VLOOKUP(CONCATENATE($AT29,$AU29,$AV29,$F29),'SKU Dist'!$E$2:$X$200,'SKU Dist'!K$1,FALSE),"")=0,"",IF($AT29<>"",VLOOKUP(CONCATENATE($AT29,$AU29,$AV29,$F29),'SKU Dist'!$E$2:$X$200,'SKU Dist'!K$1,FALSE),"")) | R29: =IF(IF($AT29<>"",VLOOKUP(CONCATENATE($AT29,$AU29,$AV29,$F29),'SKU Dist'!$E$2:$X$200,'SKU Dist'!L$1,FALSE),"")=0,"",IF($AT29<>"",VLOOKUP(CONCATENATE($AT29,$AU29,$AV29,$F29),'SKU Dist'!$E$2:$X$200,'SKU Dist'!L$1,FALSE),"")) | S29: =IF(IF($AT29<>"",VLOOKUP(CONCATENATE($AT29,$AU29,$AV29,$F29),'SKU Dist'!$E$2:$X$200,'SKU Dist'!M$1,FALSE),"")=0,"",IF($AT29<>"",VLOOKUP(CONCATENATE($AT29,$AU29,$AV29,$F29),'SKU Dist'!$E$2:$X$200,'SKU Dist'!M$1,FALSE),"")) | T29: =IF(IF($AT29<>"",VLOOKUP(CONCATENATE($AT29,$AU29,$AV29,$F29),'SKU Dist'!$E$2:$X$200,'SKU Dist'!N$1,FALSE),"")=0,"",IF($AT29<>"",VLOOKUP(CONCATENATE($AT29,$AU29,$AV29,$F29),'SKU Dist'!$E$2:$X$200,'SKU Dist'!N$1,FALSE),"")) | U29: =IF(IF($AT29<>"",VLOOKUP(CONCATENATE($AT29,$AU29,$AV29,$F29),'SKU Dist'!$E$2:$X$200,'SKU Dist'!O$1,FALSE),"")=0,"",IF($AT29<>"",VLOOKUP(CONCATENATE($AT29,$AU29,$AV29,$F29),'SKU Dist'!$E$2:$X$200,'SKU Dist'!O$1,FALSE),"")) | ... AC29: =IF(IF($AT29<>"",VLOOKUP(CONCATENATE($AT29,$AU29,$AV29,$F29),'SKU Dist'!$E$2:$X$200,'SKU Dist'!W$1,FALSE),"")=0,"",IF($AT29<>"",VLOOKUP(CONCATENATE($AT29,$AU29,$AV29,$F29),'SKU Dist'!$E$2:$X$200,'SKU Dist'!W$1,FALSE),"")) | AG29: =SUM(G29:AF29) -> 0 | AH29: 130 | AI29: =AG29*AH29 -> 0 | AT29: =IF(E29=E28,AT28,IF(B29="","",B29)) | AU29: RWBR | AV29: M
C30: VNR | D30: 081526 | E30: 3741 | F30: H | R30: =IF(IF($AT30<>"",VLOOKUP(CONCATENATE($AT30,$AU30,$AV30,$F30),'SKU Dist'!$E$2:$X$200,'SKU Dist'!L$1,FALSE),"")=0,"",IF($AT30<>"",VLOOKUP(CONCATENATE($AT30,$AU30,$AV30,$F30),'SKU Dist'!$E$2:$X$200,'SKU Dist'!L$1,FALSE),"")) | S30: =IF(IF($AT30<>"",VLOOKUP(CONCATENATE($AT30,$AU30,$AV30,$F30),'SKU Dist'!$E$2:$X$200,'SKU Dist'!M$1,FALSE),"")=0,"",IF($AT30<>"",VLOOKUP(CONCATENATE($AT30,$AU30,$AV30,$F30),'SKU Dist'!$E$2:$X$200,'SKU Dist'!M$1,FALSE),"")) | T30: =IF(IF($AT30<>"",VLOOKUP(CONCATENATE($AT30,$AU30,$AV30,$F30),'SKU Dist'!$E$2:$X$200,'SKU Dist'!N$1,FALSE),"")=0,"",IF($AT30<>"",VLOOKUP(CONCATENATE($AT30,$AU30,$AV30,$F30),'SKU Dist'!$E$2:$X$200,'SKU Dist'!N$1,FALSE),"")) | U30: =IF(IF($AT30<>"",VLOOKUP(CONCATENATE($AT30,$AU30,$AV30,$F30),'SKU Dist'!$E$2:$X$200,'SKU Dist'!O$1,FALSE),"")=0,"",IF($AT30<>"",VLOOKUP(CONCATENATE($AT30,$AU30,$AV30,$F30),'SKU Dist'!$E$2:$X$200,'SKU Dist'!O$1,FALSE),"")) | V30: =IF(IF($AT30<>"",VLOOKUP(CONCATENATE($AT30,$AU30,$AV30,$F30),'SKU Dist'!$E$2:$X$200,'SKU Dist'!P$1,FALSE),"")=0,"",IF($AT30<>"",VLOOKUP(CONCATENATE($AT30,$AU30,$AV30,$F30),'SKU Dist'!$E$2:$X$200,'SKU Dist'!P$1,FALSE),"")) | W30: =IF(IF($AT30<>"",VLOOKUP(CONCATENATE($AT30,$AU30,$AV30,$F30),'SKU Dist'!$E$2:$X$200,'SKU Dist'!Q$1,FALSE),"")=0,"",IF($AT30<>"",VLOOKUP(CONCATENATE($AT30,$AU30,$AV30,$F30),'SKU Dist'!$E$2:$X$200,'SKU Dist'!Q$1,FALSE),"")) | X30: =IF(IF($AT30<>"",VLOOKUP(CONCATENATE($AT30,$AU30,$AV30,$F30),'SKU Dist'!$E$2:$X$200,'SKU Dist'!R$1,FALSE),"")=0,"",IF($AT30<>"",VLOOKUP(CONCATENATE($AT30,$AU30,$AV30,$F30),'SKU Dist'!$E$2:$X$200,'SKU Dist'!R$1,FALSE),"")) | Y30: =IF(IF($AT30<>"",VLOOKUP(CONCATENATE($AT30,$AU30,$AV30,$F30),'SKU Dist'!$E$2:$X$200,'SKU Dist'!S$1,FALSE),"")=0,"",IF($AT30<>"",VLOOKUP(CONCATENATE($AT30,$AU30,$AV30,$F30),'SKU Dist'!$E$2:$X$200,'SKU Dist'!S$1,FALSE),"")) | ... AB30: =IF(IF($AT30<>"",VLOOKUP(CONCATENATE($AT30,$AU30,$AV30,$F30),'SKU Dist'!$E$2:$X$200,'SKU Dist'!V$1,FALSE),"")=0,"",IF($AT30<>"",VLOOKUP(CONCATENATE($AT30,$AU30,$AV30,$F30),'SKU Dist'!$E$2:$X$200,'SKU Dist'!V$1,FALSE),"")) | AG30: =SUM(G30:AF30) -> 0 | AH30: 130 | AI30: =AG30*AH30 -> 0 | AT30: =IF(E30=E29,AT29,IF(B30="","",B30)) | AU30: RWBR | AV30: M
C31: VNR | D31: 081526 | E31: 3742 | F31: B | L31: =IF(IF($AT31<>"",VLOOKUP(CONCATENATE($AT31,$AU31,$AV31,$F31),'SKU Dist'!$E$2:$X$200,'SKU Dist'!F$1,FALSE),"")=0,"",IF($AT31<>"",VLOOKUP(CONCATENATE($AT31,$AU31,$AV31,$F31),'SKU Dist'!$E$2:$X$200,'SKU Dist'!F$1,FALSE),"")) | M31: =IF(IF($AT31<>"",VLOOKUP(CONCATENATE($AT31,$AU31,$AV31,$F31),'SKU Dist'!$E$2:$X$200,'SKU Dist'!G$1,FALSE),"")=0,"",IF($AT31<>"",VLOOKUP(CONCATENATE($AT31,$AU31,$AV31,$F31),'SKU Dist'!$E$2:$X$200,'SKU Dist'!G$1,FALSE),"")) | N31: =IF(IF($AT31<>"",VLOOKUP(CONCATENATE($AT31,$AU31,$AV31,$F31),'SKU Dist'!$E$2:$X$200,'SKU Dist'!H$1,FALSE),"")=0,"",IF($AT31<>"",VLOOKUP(CONCATENATE($AT31,$AU31,$AV31,$F31),'SKU Dist'!$E$2:$X$200,'SKU Dist'!H$1,FALSE),"")) | O31: =IF(IF($AT31<>"",VLOOKUP(CONCATENATE($AT31,$AU31,$AV31,$F31),'SKU Dist'!$E$2:$X$200,'SKU Dist'!I$1,FALSE),"")=0,"",IF($AT31<>"",VLOOKUP(CONCATENATE($AT31,$AU31,$AV31,$F31),'SKU Dist'!$E$2:$X$200,'SKU Dist'!I$1,FALSE),"")) | P31: =IF(IF($AT31<>"",VLOOKUP(CONCATENATE($AT31,$AU31,$AV31,$F31),'SKU Dist'!$E$2:$X$200,'SKU Dist'!J$1,FALSE),"")=0,"",IF($AT31<>"",VLOOKUP(CONCATENATE($AT31,$AU31,$AV31,$F31),'SKU Dist'!$E$2:$X$200,'SKU Dist'!J$1,FALSE),"")) | Q31: =IF(IF($AT31<>"",VLOOKUP(CONCATENATE($AT31,$AU31,$AV31,$F31),'SKU Dist'!$E$2:$X$200,'SKU Dist'!K$1,FALSE),"")=0,"",IF($AT31<>"",VLOOKUP(CONCATENATE($AT31,$AU31,$AV31,$F31),'SKU Dist'!$E$2:$X$200,'SKU Dist'!K$1,FALSE),"")) | R31: =IF(IF($AT31<>"",VLOOKUP(CONCATENATE($AT31,$AU31,$AV31,$F31),'SKU Dist'!$E$2:$X$200,'SKU Dist'!L$1,FALSE),"")=0,"",IF($AT31<>"",VLOOKUP(CONCATENATE($AT31,$AU31,$AV31,$F31),'SKU Dist'!$E$2:$X$200,'SKU Dist'!L$1,FALSE),"")) | S31: =IF(IF($AT31<>"",VLOOKUP(CONCATENATE($AT31,$AU31,$AV31,$F31),'SKU Dist'!$E$2:$X$200,'SKU Dist'!M$1,FALSE),"")=0,"",IF($AT31<>"",VLOOKUP(CONCATENATE($AT31,$AU31,$AV31,$F31),'SKU Dist'!$E$2:$X$200,'SKU Dist'!M$1,FALSE),"")) | ... AA31: =IF(IF($AT31<>"",VLOOKUP(CONCATENATE($AT31,$AU31,$AV31,$F31),'SKU Dist'!$E$2:$X$200,'SKU Dist'!U$1,FALSE),"")=0,"",IF($AT31<>"",VLOOKUP(CONCATENATE($AT31,$AU31,$AV31,$F31),'SKU Dist'!$E$2:$X$200,'SKU Dist'!U$1,FALSE),"")) | AG31: =SUM(G31:AF31) -> 0 | AH31: 145 | AI31: =AG31*AH31 -> 0 | AU31: RWBR | AV31: W
C32: VNR | D32: 081526 | E32: 3742 | F32: D | L32: =IF(IF($AT32<>"",VLOOKUP(CONCATENATE($AT32,$AU32,$AV32,$F32),'SKU Dist'!$E$2:$X$200,'SKU Dist'!F$1,FALSE),"")=0,"",IF($AT32<>"",VLOOKUP(CONCATENATE($AT32,$AU32,$AV32,$F32),'SKU Dist'!$E$2:$X$200,'SKU Dist'!F$1,FALSE),"")) | M32: =IF(IF($AT32<>"",VLOOKUP(CONCATENATE($AT32,$AU32,$AV32,$F32),'SKU Dist'!$E$2:$X$200,'SKU Dist'!G$1,FALSE),"")=0,"",IF($AT32<>"",VLOOKUP(CONCATENATE($AT32,$AU32,$AV32,$F32),'SKU Dist'!$E$2:$X$200,'SKU Dist'!G$1,FALSE),"")) | N32: =IF(IF($AT32<>"",VLOOKUP(CONCATENATE($AT32,$AU32,$AV32,$F32),'SKU Dist'!$E$2:$X$200,'SKU Dist'!H$1,FALSE),"")=0,"",IF($AT32<>"",VLOOKUP(CONCATENATE($AT32,$AU32,$AV32,$F32),'SKU Dist'!$E$2:$X$200,'SKU Dist'!H$1,FALSE),"")) | O32: =IF(IF($AT32<>"",VLOOKUP(CONCATENATE($AT32,$AU32,$AV32,$F32),'SKU Dist'!$E$2:$X$200,'SKU Dist'!I$1,FALSE),"")=0,"",IF($AT32<>"",VLOOKUP(CONCATENATE($AT32,$AU32,$AV32,$F32),'SKU Dist'!$E$2:$X$200,'SKU Dist'!I$1,FALSE),"")) | P32: =IF(IF($AT32<>"",VLOOKUP(CONCATENATE($AT32,$AU32,$AV32,$F32),'SKU Dist'!$E$2:$X$200,'SKU Dist'!J$1,FALSE),"")=0,"",IF($AT32<>"",VLOOKUP(CONCATENATE($AT32,$AU32,$AV32,$F32),'SKU Dist'!$E$2:$X$200,'SKU Dist'!J$1,FALSE),"")) | Q32: =IF(IF($AT32<>"",VLOOKUP(CONCATENATE($AT32,$AU32,$AV32,$F32),'SKU Dist'!$E$2:$X$200,'SKU Dist'!K$1,FALSE),"")=0,"",IF($AT32<>"",VLOOKUP(CONCATENATE($AT32,$AU32,$AV32,$F32),'SKU Dist'!$E$2:$X$200,'SKU Dist'!K$1,FALSE),"")) | R32: =IF(IF($AT32<>"",VLOOKUP(CONCATENATE($AT32,$AU32,$AV32,$F32),'SKU Dist'!$E$2:$X$200,'SKU Dist'!L$1,FALSE),"")=0,"",IF($AT32<>"",VLOOKUP(CONCATENATE($AT32,$AU32,$AV32,$F32),'SKU Dist'!$E$2:$X$200,'SKU Dist'!L$1,FALSE),"")) | S32: =IF(IF($AT32<>"",VLOOKUP(CONCATENATE($AT32,$AU32,$AV32,$F32),'SKU Dist'!$E$2:$X$200,'SKU Dist'!M$1,FALSE),"")=0,"",IF($AT32<>"",VLOOKUP(CONCATENATE($AT32,$AU32,$AV32,$F32),'SKU Dist'!$E$2:$X$200,'SKU Dist'!M$1,FALSE),"")) | ... AA32: =IF(IF($AT32<>"",VLOOKUP(CONCATENATE($AT32,$AU32,$AV32,$F32),'SKU Dist'!$E$2:$X$200,'SKU Dist'!U$1,FALSE),"")=0,"",IF($AT32<>"",VLOOKUP(CONCATENATE($AT32,$AU32,$AV32,$F32),'SKU Dist'!$E$2:$X$200,'SKU Dist'!U$1,FALSE),"")) | AG32: =SUM(G32:AF32) -> 0 | AH32: 145 | AI32: =AG32*AH32 -> 0 | AU32: RWBR | AV32: W
A33: RED WING | C33: UNF | D33: 091526 | E33: 1720 | F33: B | V33: =IF(IF($AT33<>"",VLOOKUP(CONCATENATE($AT33,$AU33,$AV33,$F33),'SKU Dist'!$E$2:$X$200,'SKU Dist'!P$1,FALSE),"")=0,"",IF($AT33<>"",VLOOKUP(CONCATENATE($AT33,$AU33,$AV33,$F33),'SKU Dist'!$E$2:$X$200,'SKU Dist'!P$1,FALSE),"")) | W33: =IF(IF($AT33<>"",VLOOKUP(CONCATENATE($AT33,$AU33,$AV33,$F33),'SKU Dist'!$E$2:$X$200,'SKU Dist'!Q$1,FALSE),"")=0,"",IF($AT33<>"",VLOOKUP(CONCATENATE($AT33,$AU33,$AV33,$F33),'SKU Dist'!$E$2:$X$200,'SKU Dist'!Q$1,FALSE),"")) | X33: =IF(IF($AT33<>"",VLOOKUP(CONCATENATE($AT33,$AU33,$AV33,$F33),'SKU Dist'!$E$2:$X$200,'SKU Dist'!R$1,FALSE),"")=0,"",IF($AT33<>"",VLOOKUP(CONCATENATE($AT33,$AU33,$AV33,$F33),'SKU Dist'!$E$2:$X$200,'SKU Dist'!R$1,FALSE),"")) | Y33: =IF(IF($AT33<>"",VLOOKUP(CONCATENATE($AT33,$AU33,$AV33,$F33),'SKU Dist'!$E$2:$X$200,'SKU Dist'!S$1,FALSE),"")=0,"",IF($AT33<>"",VLOOKUP(CONCATENATE($AT33,$AU33,$AV33,$F33),'SKU Dist'!$E$2:$X$200,'SKU Dist'!S$1,FALSE),"")) | Z33: =IF(IF($AT33<>"",VLOOKUP(CONCATENATE($AT33,$AU33,$AV33,$F33),'SKU Dist'!$E$2:$X$200,'SKU Dist'!T$1,FALSE),"")=0,"",IF($AT33<>"",VLOOKUP(CONCATENATE($AT33,$AU33,$AV33,$F33),'SKU Dist'!$E$2:$X$200,'SKU Dist'!T$1,FALSE),"")) | AA33: =IF(IF($AT33<>"",VLOOKUP(CONCATENATE($AT33,$AU33,$AV33,$F33),'SKU Dist'!$E$2:$X$200,'SKU Dist'!U$1,FALSE),"")=0,"",IF($AT33<>"",VLOOKUP(CONCATENATE($AT33,$AU33,$AV33,$F33),'SKU Dist'!$E$2:$X$200,'SKU Dist'!U$1,FALSE),"")) | AB33: =IF(IF($AT33<>"",VLOOKUP(CONCATENATE($AT33,$AU33,$AV33,$F33),'SKU Dist'!$E$2:$X$200,'SKU Dist'!V$1,FALSE),"")=0,"",IF($AT33<>"",VLOOKUP(CONCATENATE($AT33,$AU33,$AV33,$F33),'SKU Dist'!$E$2:$X$200,'SKU Dist'!V$1,FALSE),"")) | AG33: =SUM(G33:AF33) -> 0 | AH33: 135 | AI33: =AG33*AH33 -> 0 | AT33: =IF(E33=E30,AT30,IF(B33="","",B33)) | AU33: RWBR | AV33: M
A34: Construct | C34: UNF | D34: 091526 | E34: 1720 | F34: D | N34: =IF(IF($AT34<>"",VLOOKUP(CONCATENATE($AT34,$AU34,$AV34,$F34),'SKU Dist'!$E$2:$X$200,'SKU Dist'!H$1,FALSE),"")=0,"",IF($AT34<>"",VLOOKUP(CONCATENATE($AT34,$AU34,$AV34,$F34),'SKU Dist'!$E$2:$X$200,'SKU Dist'!H$1,FALSE),"")) | O34: =IF(IF($AT34<>"",VLOOKUP(CONCATENATE($AT34,$AU34,$AV34,$F34),'SKU Dist'!$E$2:$X$200,'SKU Dist'!I$1,FALSE),"")=0,"",IF($AT34<>"",VLOOKUP(CONCATENATE($AT34,$AU34,$AV34,$F34),'SKU Dist'!$E$2:$X$200,'SKU Dist'!I$1,FALSE),"")) | P34: =IF(IF($AT34<>"",VLOOKUP(CONCATENATE($AT34,$AU34,$AV34,$F34),'SKU Dist'!$E$2:$X$200,'SKU Dist'!J$1,FALSE),"")=0,"",IF($AT34<>"",VLOOKUP(CONCATENATE($AT34,$AU34,$AV34,$F34),'SKU Dist'!$E$2:$X$200,'SKU Dist'!J$1,FALSE),"")) | Q34: =IF(IF($AT34<>"",VLOOKUP(CONCATENATE($AT34,$AU34,$AV34,$F34),'SKU Dist'!$E$2:$X$200,'SKU Dist'!K$1,FALSE),"")=0,"",IF($AT34<>"",VLOOKUP(CONCATENATE($AT34,$AU34,$AV34,$F34),'SKU Dist'!$E$2:$X$200,'SKU Dist'!K$1,FALSE),"")) | R34: =IF(IF($AT34<>"",VLOOKUP(CONCATENATE($AT34,$AU34,$AV34,$F34),'SKU Dist'!$E$2:$X$200,'SKU Dist'!L$1,FALSE),"")=0,"",IF($AT34<>"",VLOOKUP(CONCATENATE($AT34,$AU34,$AV34,$F34),'SKU Dist'!$E$2:$X$200,'SKU Dist'!L$1,FALSE),"")) | S34: =IF(IF($AT34<>"",VLOOKUP(CONCATENATE($AT34,$AU34,$AV34,$F34),'SKU Dist'!$E$2:$X$200,'SKU Dist'!M$1,FALSE),"")=0,"",IF($AT34<>"",VLOOKUP(CONCATENATE($AT34,$AU34,$AV34,$F34),'SKU Dist'!$E$2:$X$200,'SKU Dist'!M$1,FALSE),"")) | T34: =IF(IF($AT34<>"",VLOOKUP(CONCATENATE($AT34,$AU34,$AV34,$F34),'SKU Dist'!$E$2:$X$200,'SKU Dist'!N$1,FALSE),"")=0,"",IF($AT34<>"",VLOOKUP(CONCATENATE($AT34,$AU34,$AV34,$F34),'SKU Dist'!$E$2:$X$200,'SKU Dist'!N$1,FALSE),"")) | U34: =IF(IF($AT34<>"",VLOOKUP(CONCATENATE($AT34,$AU34,$AV34,$F34),'SKU Dist'!$E$2:$X$200,'SKU Dist'!O$1,FALSE),"")=0,"",IF($AT34<>"",VLOOKUP(CONCATENATE($AT34,$AU34,$AV34,$F34),'SKU Dist'!$E$2:$X$200,'SKU Dist'!O$1,FALSE),"")) | ... AC34: =IF(IF($AT34<>"",VLOOKUP(CONCATENATE($AT34,$AU34,$AV34,$F34),'SKU Dist'!$E$2:$X$200,'SKU Dist'!W$1,FALSE),"")=0,"",IF($AT34<>"",VLOOKUP(CONCATENATE($AT34,$AU34,$AV34,$F34),'SKU Dist'!$E$2:$X$200,'SKU Dist'!W$1,FALSE),"")) | AG34: =SUM(G34:AF34) -> 0 | AH34: 135 | AI34: =AG34*AH34 -> 0 | AT34: =IF(E34=E33,AT33,IF(B34="","",B34)) | AU34: RWBR | AV34: M
A35: =SUM(AG33:AG44) -> 38 | C35: UNF | D35: 091526 | E35: 1720 | F35: E2 | N35: =IF(IF($AT35<>"",VLOOKUP(CONCATENATE($AT35,$AU35,$AV35,$F35),'SKU Dist'!$E$2:$X$200,'SKU Dist'!H$1,FALSE),"")=0,"",IF($AT35<>"",VLOOKUP(CONCATENATE($AT35,$AU35,$AV35,$F35),'SKU Dist'!$E$2:$X$200,'SKU Dist'!H$1,FALSE),"")) | O35: =IF(IF($AT35<>"",VLOOKUP(CONCATENATE($AT35,$AU35,$AV35,$F35),'SKU Dist'!$E$2:$X$200,'SKU Dist'!I$1,FALSE),"")=0,"",IF($AT35<>"",VLOOKUP(CONCATENATE($AT35,$AU35,$AV35,$F35),'SKU Dist'!$E$2:$X$200,'SKU Dist'!I$1,FALSE),"")) | P35: =IF(IF($AT35<>"",VLOOKUP(CONCATENATE($AT35,$AU35,$AV35,$F35),'SKU Dist'!$E$2:$X$200,'SKU Dist'!J$1,FALSE),"")=0,"",IF($AT35<>"",VLOOKUP(CONCATENATE($AT35,$AU35,$AV35,$F35),'SKU Dist'!$E$2:$X$200,'SKU Dist'!J$1,FALSE),"")) | Q35: =IF(IF($AT35<>"",VLOOKUP(CONCATENATE($AT35,$AU35,$AV35,$F35),'SKU Dist'!$E$2:$X$200,'SKU Dist'!K$1,FALSE),"")=0,"",IF($AT35<>"",VLOOKUP(CONCATENATE($AT35,$AU35,$AV35,$F35),'SKU Dist'!$E$2:$X$200,'SKU Dist'!K$1,FALSE),"")) | R35: =IF(IF($AT35<>"",VLOOKUP(CONCATENATE($AT35,$AU35,$AV35,$F35),'SKU Dist'!$E$2:$X$200,'SKU Dist'!L$1,FALSE),"")=0,"",IF($AT35<>"",VLOOKUP(CONCATENATE($AT35,$AU35,$AV35,$F35),'SKU Dist'!$E$2:$X$200,'SKU Dist'!L$1,FALSE),"")) | S35: =IF(IF($AT35<>"",VLOOKUP(CONCATENATE($AT35,$AU35,$AV35,$F35),'SKU Dist'!$E$2:$X$200,'SKU Dist'!M$1,FALSE),"")=0,"",IF($AT35<>"",VLOOKUP(CONCATENATE($AT35,$AU35,$AV35,$F35),'SKU Dist'!$E$2:$X$200,'SKU Dist'!M$1,FALSE),"")) | T35: =IF(IF($AT35<>"",VLOOKUP(CONCATENATE($AT35,$AU35,$AV35,$F35),'SKU Dist'!$E$2:$X$200,'SKU Dist'!N$1,FALSE),"")=0,"",IF($AT35<>"",VLOOKUP(CONCATENATE($AT35,$AU35,$AV35,$F35),'SKU Dist'!$E$2:$X$200,'SKU Dist'!N$1,FALSE),"")) | U35: =IF(IF($AT35<>"",VLOOKUP(CONCATENATE($AT35,$AU35,$AV35,$F35),'SKU Dist'!$E$2:$X$200,'SKU Dist'!O$1,FALSE),"")=0,"",IF($AT35<>"",VLOOKUP(CONCATENATE($AT35,$AU35,$AV35,$F35),'SKU Dist'!$E$2:$X$200,'SKU Dist'!O$1,FALSE),"")) | ... AC35: =IF(IF($AT35<>"",VLOOKUP(CONCATENATE($AT35,$AU35,$AV35,$F35),'SKU Dist'!$E$2:$X$200,'SKU Dist'!W$1,FALSE),"")=0,"",IF($AT35<>"",VLOOKUP(CONCATENATE($AT35,$AU35,$AV35,$F35),'SKU Dist'!$E$2:$X$200,'SKU Dist'!W$1,FALSE),"")) | AG35: =SUM(G35:AF35) -> 0 | AH35: 135 | AI35: =AG35*AH35 -> 0 | AT35: =IF(E35=E34,AT34,IF(B35="","",B35)) | AU35: RWBR | AV35: M
A36: =SUM(AI33:AI44) -> 5415 | C36: UNF | D36: 091526 | E36: 1720 | F36: H | R36: =IF(IF($AT36<>"",VLOOKUP(CONCATENATE($AT36,$AU36,$AV36,$F36),'SKU Dist'!$E$2:$X$200,'SKU Dist'!L$1,FALSE),"")=0,"",IF($AT36<>"",VLOOKUP(CONCATENATE($AT36,$AU36,$AV36,$F36),'SKU Dist'!$E$2:$X$200,'SKU Dist'!L$1,FALSE),"")) | S36: =IF(IF($AT36<>"",VLOOKUP(CONCATENATE($AT36,$AU36,$AV36,$F36),'SKU Dist'!$E$2:$X$200,'SKU Dist'!M$1,FALSE),"")=0,"",IF($AT36<>"",VLOOKUP(CONCATENATE($AT36,$AU36,$AV36,$F36),'SKU Dist'!$E$2:$X$200,'SKU Dist'!M$1,FALSE),"")) | T36: =IF(IF($AT36<>"",VLOOKUP(CONCATENATE($AT36,$AU36,$AV36,$F36),'SKU Dist'!$E$2:$X$200,'SKU Dist'!N$1,FALSE),"")=0,"",IF($AT36<>"",VLOOKUP(CONCATENATE($AT36,$AU36,$AV36,$F36),'SKU Dist'!$E$2:$X$200,'SKU Dist'!N$1,FALSE),"")) | U36: =IF(IF($AT36<>"",VLOOKUP(CONCATENATE($AT36,$AU36,$AV36,$F36),'SKU Dist'!$E$2:$X$200,'SKU Dist'!O$1,FALSE),"")=0,"",IF($AT36<>"",VLOOKUP(CONCATENATE($AT36,$AU36,$AV36,$F36),'SKU Dist'!$E$2:$X$200,'SKU Dist'!O$1,FALSE),"")) | V36: =IF(IF($AT36<>"",VLOOKUP(CONCATENATE($AT36,$AU36,$AV36,$F36),'SKU Dist'!$E$2:$X$200,'SKU Dist'!P$1,FALSE),"")=0,"",IF($AT36<>"",VLOOKUP(CONCATENATE($AT36,$AU36,$AV36,$F36),'SKU Dist'!$E$2:$X$200,'SKU Dist'!P$1,FALSE),"")) | W36: =IF(IF($AT36<>"",VLOOKUP(CONCATENATE($AT36,$AU36,$AV36,$F36),'SKU Dist'!$E$2:$X$200,'SKU Dist'!Q$1,FALSE),"")=0,"",IF($AT36<>"",VLOOKUP(CONCATENATE($AT36,$AU36,$AV36,$F36),'SKU Dist'!$E$2:$X$200,'SKU Dist'!Q$1,FALSE),"")) | X36: =IF(IF($AT36<>"",VLOOKUP(CONCATENATE($AT36,$AU36,$AV36,$F36),'SKU Dist'!$E$2:$X$200,'SKU Dist'!R$1,FALSE),"")=0,"",IF($AT36<>"",VLOOKUP(CONCATENATE($AT36,$AU36,$AV36,$F36),'SKU Dist'!$E$2:$X$200,'SKU Dist'!R$1,FALSE),"")) | Y36: =IF(IF($AT36<>"",VLOOKUP(CONCATENATE($AT36,$AU36,$AV36,$F36),'SKU Dist'!$E$2:$X$200,'SKU Dist'!S$1,FALSE),"")=0,"",IF($AT36<>"",VLOOKUP(CONCATENATE($AT36,$AU36,$AV36,$F36),'SKU Dist'!$E$2:$X$200,'SKU Dist'!S$1,FALSE),"")) | ... AB36: =IF(IF($AT36<>"",VLOOKUP(CONCATENATE($AT36,$AU36,$AV36,$F36),'SKU Dist'!$E$2:$X$200,'SKU Dist'!V$1,FALSE),"")=0,"",IF($AT36<>"",VLOOKUP(CONCATENATE($AT36,$AU36,$AV36,$F36),'SKU Dist'!$E$2:$X$200,'SKU Dist'!V$1,FALSE),"")) | AG36: =SUM(G36:AF36) -> 0 | AH36: 135 | AI36: =AG36*AH36 -> 0 | AU36: RWBR | AV36: M
C37: UNF | D37: 091526 | E37: 2668 | F37: B | V37: =IF(IF($AT37<>"",VLOOKUP(CONCATENATE($AT37,$AU37,$AV37,$F37),'SKU Dist'!$E$2:$X$200,'SKU Dist'!P$1,FALSE),"")=0,"",IF($AT37<>"",VLOOKUP(CONCATENATE($AT37,$AU37,$AV37,$F37),'SKU Dist'!$E$2:$X$200,'SKU Dist'!P$1,FALSE),"")) | W37: =IF(IF($AT37<>"",VLOOKUP(CONCATENATE($AT37,$AU37,$AV37,$F37),'SKU Dist'!$E$2:$X$200,'SKU Dist'!Q$1,FALSE),"")=0,"",IF($AT37<>"",VLOOKUP(CONCATENATE($AT37,$AU37,$AV37,$F37),'SKU Dist'!$E$2:$X$200,'SKU Dist'!Q$1,FALSE),"")) | X37: =IF(IF($AT37<>"",VLOOKUP(CONCATENATE($AT37,$AU37,$AV37,$F37),'SKU Dist'!$E$2:$X$200,'SKU Dist'!R$1,FALSE),"")=0,"",IF($AT37<>"",VLOOKUP(CONCATENATE($AT37,$AU37,$AV37,$F37),'SKU Dist'!$E$2:$X$200,'SKU Dist'!R$1,FALSE),"")) | Y37: =IF(IF($AT37<>"",VLOOKUP(CONCATENATE($AT37,$AU37,$AV37,$F37),'SKU Dist'!$E$2:$X$200,'SKU Dist'!S$1,FALSE),"")=0,"",IF($AT37<>"",VLOOKUP(CONCATENATE($AT37,$AU37,$AV37,$F37),'SKU Dist'!$E$2:$X$200,'SKU Dist'!S$1,FALSE),"")) | Z37: =IF(IF($AT37<>"",VLOOKUP(CONCATENATE($AT37,$AU37,$AV37,$F37),'SKU Dist'!$E$2:$X$200,'SKU Dist'!T$1,FALSE),"")=0,"",IF($AT37<>"",VLOOKUP(CONCATENATE($AT37,$AU37,$AV37,$F37),'SKU Dist'!$E$2:$X$200,'SKU Dist'!T$1,FALSE),"")) | AA37: =IF(IF($AT37<>"",VLOOKUP(CONCATENATE($AT37,$AU37,$AV37,$F37),'SKU Dist'!$E$2:$X$200,'SKU Dist'!U$1,FALSE),"")=0,"",IF($AT37<>"",VLOOKUP(CONCATENATE($AT37,$AU37,$AV37,$F37),'SKU Dist'!$E$2:$X$200,'SKU Dist'!U$1,FALSE),"")) | AB37: =IF(IF($AT37<>"",VLOOKUP(CONCATENATE($AT37,$AU37,$AV37,$F37),'SKU Dist'!$E$2:$X$200,'SKU Dist'!V$1,FALSE),"")=0,"",IF($AT37<>"",VLOOKUP(CONCATENATE($AT37,$AU37,$AV37,$F37),'SKU Dist'!$E$2:$X$200,'SKU Dist'!V$1,FALSE),"")) | AG37: =SUM(G37:AF37) -> 0 | AH37: 145 | AI37: =AG37*AH37 -> 0 | AT37: =IF(E37=E34,AT34,IF(B37="","",B37)) | AU37: RWBR | AV37: M
C38: UNF | D38: 091526 | E38: 2668 | F38: D | N38: =IF(IF($AT38<>"",VLOOKUP(CONCATENATE($AT38,$AU38,$AV38,$F38),'SKU Dist'!$E$2:$X$200,'SKU Dist'!H$1,FALSE),"")=0,"",IF($AT38<>"",VLOOKUP(CONCATENATE($AT38,$AU38,$AV38,$F38),'SKU Dist'!$E$2:$X$200,'SKU Dist'!H$1,FALSE),"")) | O38: =IF(IF($AT38<>"",VLOOKUP(CONCATENATE($AT38,$AU38,$AV38,$F38),'SKU Dist'!$E$2:$X$200,'SKU Dist'!I$1,FALSE),"")=0,"",IF($AT38<>"",VLOOKUP(CONCATENATE($AT38,$AU38,$AV38,$F38),'SKU Dist'!$E$2:$X$200,'SKU Dist'!I$1,FALSE),"")) | P38: =IF(IF($AT38<>"",VLOOKUP(CONCATENATE($AT38,$AU38,$AV38,$F38),'SKU Dist'!$E$2:$X$200,'SKU Dist'!J$1,FALSE),"")=0,"",IF($AT38<>"",VLOOKUP(CONCATENATE($AT38,$AU38,$AV38,$F38),'SKU Dist'!$E$2:$X$200,'SKU Dist'!J$1,FALSE),"")) | Q38: =IF(IF($AT38<>"",VLOOKUP(CONCATENATE($AT38,$AU38,$AV38,$F38),'SKU Dist'!$E$2:$X$200,'SKU Dist'!K$1,FALSE),"")=0,"",IF($AT38<>"",VLOOKUP(CONCATENATE($AT38,$AU38,$AV38,$F38),'SKU Dist'!$E$2:$X$200,'SKU Dist'!K$1,FALSE),"")) | R38: =IF(IF($AT38<>"",VLOOKUP(CONCATENATE($AT38,$AU38,$AV38,$F38),'SKU Dist'!$E$2:$X$200,'SKU Dist'!L$1,FALSE),"")=0,"",IF($AT38<>"",VLOOKUP(CONCATENATE($AT38,$AU38,$AV38,$F38),'SKU Dist'!$E$2:$X$200,'SKU Dist'!L$1,FALSE),"")) | S38: 1 | T38: 1 | U38: 2 | V38: 2 | W38: 2 | X38: 2 | Y38: 1 | Z38: 2 | AA38: =IF(IF($AT38<>"",VLOOKUP(CONCATENATE($AT38,$AU38,$AV38,$F38),'SKU Dist'!$E$2:$X$200,'SKU Dist'!U$1,FALSE),"")=0,"",IF($AT38<>"",VLOOKUP(CONCATENATE($AT38,$AU38,$AV38,$F38),'SKU Dist'!$E$2:$X$200,'SKU Dist'!U$1,FALSE),"")) | AB38: =IF(IF($AT38<>"",VLOOKUP(CONCATENATE($AT38,$AU38,$AV38,$F38),'SKU Dist'!$E$2:$X$200,'SKU Dist'!V$1,FALSE),"")=0,"",IF($AT38<>"",VLOOKUP(CONCATENATE($AT38,$AU38,$AV38,$F38),'SKU Dist'!$E$2:$X$200,'SKU Dist'!V$1,FALSE),"")) | AC38: =IF(IF($AT38<>"",VLOOKUP(CONCATENATE($AT38,$AU38,$AV38,$F38),'SKU Dist'!$E$2:$X$200,'SKU Dist'!W$1,FALSE),"")=0,"",IF($AT38<>"",VLOOKUP(CONCATENATE($AT38,$AU38,$AV38,$F38),'SKU Dist'!$E$2:$X$200,'SKU Dist'!W$1,FALSE),"")) | AG38: =SUM(G38:AF38) -> 13 | AH38: 145 | AI38: =AG38*AH38 -> 1885 | AT38: =IF(E38=E37,AT37,IF(B38="","",B38)) | AU38: RWBR | AV38: M
